Workbook
Name ExterneDaten_1_1: 0
Name ExterneDaten_1_10: 0
Name ExterneDaten_1_11: 0
Name ExterneDaten_1_12: 0
Name ExterneDaten_1_13: 0
Name ExterneDaten_1_2: 0
Name ExterneDaten_1_3: 0
Name ExterneDaten_1_4: 0
Name ExterneDaten_1_5: 0
Name ExterneDaten_1_6: 0
Name ExterneDaten_1_7: 0
Name ExterneDaten_1_8: 0
Name ExterneDaten_1_9: 0

Sheet offen_aus_25
A1: Name | B1: ID | C1: Befreit? | D1: Offene Stunden aus 25 (bis 31.12.2025) | E1: Stunden ab 26 | F1: noch immer offene Stunden nach Ausgleich
A2: Abdelouahed El Haddoui | B2: 826067 | D2: 0 | E2: =VLOOKUP(B2,Gesamtstunden_26!B:I,8,0) | F2: =D2-E2
A3: Adelheid Henrich | B3: 136454 | D3: 3.3333333 | E3: =VLOOKUP(B3,Gesamtstunden_26!B:I,8,0) | F3: =D3-E3
A4: Adrian Deptuch | B4: 216555 | D4: 4.6733333 | E4: =VLOOKUP(B4,Gesamtstunden_26!B:I,8,0) | F4: =D4-E4
A5: Adrian Rölver | B5: 298763 | D5: 5.6666667 | E5: =VLOOKUP(B5,Gesamtstunden_26!B:I,8,0) | F5: =D5-E5
A6: Aicha Boutasfat | B6: 276971 | D6: 0 | E6: =VLOOKUP(B6,Gesamtstunden_26!B:I,8,0) | F6: =D6-E6
A7: Aileen Taschner | B7: 214380 | D7: 0 | E7: =VLOOKUP(B7,Gesamtstunden_26!B:I,8,0) | F7: =D7-E7
A8: Alberto Kästner Fritsch | B8: 794748 | D8: 3 | E8: =VLOOKUP(B8,Gesamtstunden_26!B:I,8,0) | F8: =D8-E8
A9: Aleksandra Aleksic-Bardjesteh | B9: 662108 | D9: 0 | E9: =VLOOKUP(B9,Gesamtstunden_26!B:I,8,0) | F9: =D9-E9
A10: Alena Klein | B10: 742934 | D10: 14 | E10: =VLOOKUP(B10,Gesamtstunden_26!B:I,8,0) | F10: =D10-E10
A11: Alena Korbut | B11: 509374 | D11: 0 | E11: =VLOOKUP(B11,Gesamtstunden_26!B:I,8,0) | F11: =D11-E11
A12: Alexander Epp | B12: 703098 | D12: 9.1666667 | E12: =VLOOKUP(B12,Gesamtstunden_26!B:I,8,0) | F12: =D12-E12
A13: Alexander Roppelt | B13: 720432 | D13: 0.33333333 | E13: =VLOOKUP(B13,Gesamtstunden_26!B:I,8,0) | F13: =D13-E13
... A814: Zacharias Funk | B814: 746046 | D814: 0 | E814: =VLOOKUP(B814,Gesamtstunden_26!B:I,8,0) | F814: =D814-E814

Sheet Gesamtstunden_26
A1: Name | B1: ID | C1: Befreit? | D1: Vereinseintritt | E1: Offene Stunden aus 25 | F1: Soll-Stunden für 26 | G1: Offene Stunden für 26 | H1: für 26 zählende Stunden | I1: Gesamtstunden (in 26 geleistet) | J1: Öffentlichkeitsarbeit | K1: Fairteilerreinigung | L1: Abholung Nicht-Premium | M1: Fairteilungen (z.B. Friedensgemeinde) | N1: Anlieferung (z.B. Friedensgemeinde) | O1: Probeabholungen
A2: Abdelouahed El Haddoui | B2: 826067 | E2: 0 | F2: 6 | G2: =F2-H2 | H2: =I2-E2 | I2: =SUM(J2:O2) | J2: =SUMIF(#REF!,$B2,#REF!) | K2: =COUNTIF(#REF!,$B2)*1/2 | L2: =COUNTIF(#REF!,$B2)*1/3 | M2: =COUNTIF(#REF!,$B2)*3/4 | N2: =COUNTIF(#REF!,$B2)*1/2 | O2: =COUNTIF(#REF!,$B2)*1/3
A3: Adelheid Henrich | B3: 136454 | E3: 3.3333333 | F3: 6 | G3: =F3-H3 | H3: =I3-E3 | I3: =SUM(J3:O3) | J3: =SUMIF(#REF!,$B3,#REF!) | K3: =COUNTIF(#REF!,$B3)*1/2 | L3: =COUNTIF(#REF!,$B3)*1/3 | M3: =COUNTIF(#REF!,$B3)*3/4 | N3: =COUNTIF(#REF!,$B3)*1/2 | O3: =COUNTIF(#REF!,$B3)*1/3
A4: Adrian Deptuch | B4: 216555 | E4: 4.6733333 | F4: 6 | G4: =F4-H4 | H4: =I4-E4 | I4: =SUM(J4:O4) | J4: =SUMIF(#REF!,$B4,#REF!) | K4: =COUNTIF(#REF!,$B4)*1/2 | L4: =COUNTIF(#REF!,$B4)*1/3 | M4: =COUNTIF(#REF!,$B4)*3/4 | N4: =COUNTIF(#REF!,$B4)*1/2 | O4: =COUNTIF(#REF!,$B4)*1/3
A5: Adrian Rölver | B5: 298763 | E5: 5.6666667 | F5: 6 | G5: =F5-H5 | H5: =I5-E5 | I5: =SUM(J5:O5) | J5: =SUMIF(#REF!,$B5,#REF!) | K5: =COUNTIF(#REF!,$B5)*1/2 | L5: =COUNTIF(#REF!,$B5)*1/3 | M5: =COUNTIF(#REF!,$B5)*3/4 | N5: =COUNTIF(#REF!,$B5)*1/2 | O5: =COUNTIF(#REF!,$B5)*1/3
A6: Aicha Boutasfat | B6: 276971 | C6: BV (alte Regelung, unbefristet 100%) | E6: 0 | F6: 0 | G6: =F6-H6 | H6: =I6-E6 | I6: =SUM(J6:O6) | J6: =SUMIF(#REF!,$B6,#REF!) | K6: =COUNTIF(#REF!,$B6)*1/2 | L6: =COUNTIF(#REF!,$B6)*1/3 | M6: =COUNTIF(#REF!,$B6)*3/4 | N6: =COUNTIF(#REF!,$B6)*1/2 | O6: =COUNTIF(#REF!,$B6)*1/3
A7: Aileen Taschner | B7: 214380 | E7: 0 | F7: 6 | G7: =F7-H7 | H7: =I7-E7 | I7: =SUM(J7:O7) | J7: =SUMIF(#REF!,$B7,#REF!) | K7: =COUNTIF(#REF!,$B7)*1/2 | L7: =COUNTIF(#REF!,$B7)*1/3 | M7: =COUNTIF(#REF!,$B7)*3/4 | N7: =COUNTIF(#REF!,$B7)*1/2 | O7: =COUNTIF(#REF!,$B7)*1/3
A8: Alberto Kästner Fritsch | B8: 794748 | D8: 45845 | E8: 3 | F8: 6 | G8: =F8-H8 | H8: =I8-E8 | I8: =SUM(J8:O8) | J8: =SUMIF(#REF!,$B8,#REF!) | K8: =COUNTIF(#REF!,$B8)*1/2 | L8: =COUNTIF(#REF!,$B8)*1/3 | M8: =COUNTIF(#REF!,$B8)*3/4 | N8: =COUNTIF(#REF!,$B8)*1/2 | O8: =COUNTIF(#REF!,$B8)*1/3
A9: Aleksandra Aleksic-Bardjesteh | B9: 662108 | D9: 45228 | E9: 0 | F9: 6 | G9: =F9-H9 | H9: =I9-E9 | I9: =SUM(J9:O9) | J9: =SUMIF(#REF!,$B9,#REF!) | K9: =COUNTIF(#REF!,$B9)*1/2 | L9: =COUNTIF(#REF!,$B9)*1/3 | M9: =COUNTIF(#REF!,$B9)*3/4 | N9: =COUNTIF(#REF!,$B9)*1/2 | O9: =COUNTIF(#REF!,$B9)*1/3
A10: Alena Klein | B10: 742934 | D10: 45097 | E10: 14 | F10: 6 | G10: =F10-H10 | H10: =I10-E10 | I10: =SUM(J10:O10) | J10: =SUMIF(#REF!,$B10,#REF!) | K10: =COUNTIF(#REF!,$B10)*1/2 | L10: =COUNTIF(#REF!,$B10)*1/3 | M10: =COUNTIF(#REF!,$B10)*3/4 | N10: =COUNTIF(#REF!,$B10)*1/2 | O10: =COUNTIF(#REF!,$B10)*1/3
A11: Alena Korbut | B11: 509374 | E11: 0 | F11: 6 | G11: =F11-H11 | H11: =I11-E11 | I11: =SUM(J11:O11) | J11: =SUMIF(#REF!,$B11,#REF!) | K11: =COUNTIF(#REF!,$B11)*1/2 | L11: =COUNTIF(#REF!,$B11)*1/3 | M11: =COUNTIF(#REF!,$B11)*3/4 | N11: =COUNTIF(#REF!,$B11)*1/2 | O11: =COUNTIF(#REF!,$B11)*1/3
A12: Alexander Epp | B12: 703098 | D12: 45058 | E12: 9.1666667 | F12: 6 | G12: =F12-H12 | H12: =I12-E12 | I12: =SUM(J12:O12) | J12: =SUMIF(#REF!,$B12,#REF!) | K12: =COUNTIF(#REF!,$B12)*1/2 | L12: =COUNTIF(#REF!,$B12)*1/3 | M12: =COUNTIF(#REF!,$B12)*3/4 | N12: =COUNTIF(#REF!,$B12)*1/2 | O12: =COUNTIF(#REF!,$B12)*1/3
A13: Alexander Roppelt | B13: 720432 | D13: 45061 | E13: 0.33333333 | F13: 6 | G13: =F13-H13 | H13: =I13-E13 | I13: =SUM(J13:O13) | J13: =SUMIF(#REF!,$B13,#REF!) | K13: =COUNTIF(#REF!,$B13)*1/2 | L13: =COUNTIF(#REF!,$B13)*1/3 | M13: =COUNTIF(#REF!,$B13)*3/4 | N13: =COUNTIF(#REF!,$B13)*1/2 | O13: =COUNTIF(#REF!,$B13)*1/3
A14: Alexander Stecher | B14: 557897 | E14: 0 | F14: 6 | G14: =F14-H14 | H14: =I14-E14 | I14: =SUM(J14:O14) | J14: =SUMIF(#REF!,$B14,#REF!) | K14: =COUNTIF(#REF!,$B14)*1/2 | L14: =COUNTIF(#REF!,$B14)*1/3 | M14: =COUNTIF(#REF!,$B14)*3/4 | N14: =COUNTIF(#REF!,$B14)*1/2 | O14: =COUNTIF(#REF!,$B14)*1/3
A15: Alexander Vainshtein | B15: 871845 | D15: 45612 | E15: 0 | F15: 6 | G15: =F15-H15 | H15: =I15-E15 | I15: =SUM(J15:O15) | J15: =SUMIF(#REF!,$B15,#REF!) | K15: =COUNTIF(#REF!,$B15)*1/2 | L15: =COUNTIF(#REF!,$B15)*1/3 | M15: =COUNTIF(#REF!,$B15)*3/4 | N15: =COUNTIF(#REF!,$B15)*1/2 | O15: =COUNTIF(#REF!,$B15)*1/3
A16: Alexandra Arend | B16: 643035 | E16: 5.3333333 | F16: 6 | G16: =F16-H16 | H16: =I16-E16 | I16: =SUM(J16:O16) | J16: =SUMIF(#REF!,$B16,#REF!) | K16: =COUNTIF(#REF!,$B16)*1/2 | L16: =COUNTIF(#REF!,$B16)*1/3 | M16: =COUNTIF(#REF!,$B16)*3/4 | N16: =COUNTIF(#REF!,$B16)*1/2 | O16: =COUNTIF(#REF!,$B16)*1/3
A17: Alexandra Jansen | B17: 654688 | C17: GdB 50 | E17: 0 | F17: 0 | G17: =F17-H17 | H17: =I17-E17 | I17: =SUM(J17:O17) | J17: =SUMIF(#REF!,$B17,#REF!) | K17: =COUNTIF(#REF!,$B17)*1/2 | L17: =COUNTIF(#REF!,$B17)*1/3 | M17: =COUNTIF(#REF!,$B17)*3/4 | N17: =COUNTIF(#REF!,$B17)*1/2 | O17: =COUNTIF(#REF!,$B17)*1/3
A18: Alexandra Päzolt | B18: 964211 | D18: 45985 | E18: 0 | F18: 6 | G18: =F18-H18 | H18: =I18-E18 | I18: =SUM(J18:O18) | J18: =SUMIF(#REF!,$B18,#REF!) | K18: =COUNTIF(#REF!,$B18)*1/2 | L18: =COUNTIF(#REF!,$B18)*1/3 | M18: =COUNTIF(#REF!,$B18)*3/4 | N18: =COUNTIF(#REF!,$B18)*1/2 | O18: =COUNTIF(#REF!,$B18)*1/3
A19: Ali Kabouch | B19: 597806 | E19: 0 | F19: 6 | G19: =F19-H19 | H19: =I19-E19 | I19: =SUM(J19:O19) | J19: =SUMIF(#REF!,$B19,#REF!) | K19: =COUNTIF(#REF!,$B19)*1/2 | L19: =COUNTIF(#REF!,$B19)*1/3 | M19: =COUNTIF(#REF!,$B19)*3/4 | N19: =COUNTIF(#REF!,$B19)*1/2 | O19: =COUNTIF(#REF!,$B19)*1/3
A20: Alicia Artschwager | B20: 565142 | E20: 0 | F20: 6 | G20: =F20-H20 | H20: =I20-E20 | I20: =SUM(J20:O20) | J20: =SUMIF(#REF!,$B20,#REF!) | K20: =COUNTIF(#REF!,$B20)*1/2 | L20: =COUNTIF(#REF!,$B20)*1/3 | M20: =COUNTIF(#REF!,$B20)*3/4 | N20: =COUNTIF(#REF!,$B20)*1/2 | O20: =COUNTIF(#REF!,$B20)*1/3
A21: Alicia Koch | B21: 248981 | C21: Alter | E21: 0 | F21: 0 | G21: =F21-H21 | H21: =I21-E21 | I21: =SUM(J21:O21) | J21: =SUMIF(#REF!,$B21,#REF!) | K21: =COUNTIF(#REF!,$B21)*1/2 | L21: =COUNTIF(#REF!,$B21)*1/3 | M21: =COUNTIF(#REF!,$B21)*3/4 | N21: =COUNTIF(#REF!,$B21)*1/2 | O21: =COUNTIF(#REF!,$B21)*1/3
A22: Alicia Mohn | B22: 617287 | E22: 12 | F22: 6 | G22: =F22-H22 | H22: =I22-E22 | I22: =SUM(J22:O22) | J22: =SUMIF(#REF!,$B22,#REF!) | K22: =COUNTIF(#REF!,$B22)*1/2 | L22: =COUNTIF(#REF!,$B22)*1/3 | M22: =COUNTIF(#REF!,$B22)*3/4 | N22: =COUNTIF(#REF!,$B22)*1/2 | O22: =COUNTIF(#REF!,$B22)*1/3
A23: Alicia Schrader | B23: 805780 | D23: 45531 | E23: 6.6666667 | F23: 6 | G23: =F23-H23 | H23: =I23-E23 | I23: =SUM(J23:O23) | J23: =SUMIF(#REF!,$B23,#REF!) | K23: =COUNTIF(#REF!,$B23)*1/2 | L23: =COUNTIF(#REF!,$B23)*1/3 | M23: =COUNTIF(#REF!,$B23)*3/4 | N23: =COUNTIF(#REF!,$B23)*1/2 | O23: =COUNTIF(#REF!,$B23)*1/3
A24: Alina Braun | B24: 480180 | D24: 45171 | E24: 0 | F24: 6 | G24: =F24-H24 | H24: =I24-E24 | I24: =SUM(J24:O24) | J24: =SUMIF(#REF!,$B24,#REF!) | K24: =COUNTIF(#REF!,$B24)*1/2 | L24: =COUNTIF(#REF!,$B24)*1/3 | M24: =COUNTIF(#REF!,$B24)*3/4 | N24: =COUNTIF(#REF!,$B24)*1/2 | O24: =COUNTIF(#REF!,$B24)*1/3
A25: Alina Panzenböck | B25: 486886 | D25: 45845 | E25: 3 | F25: 6 | G25: =F25-H25 | H25: =I25-E25 | I25: =SUM(J25:O25) | J25: =SUMIF(#REF!,$B25,#REF!) | K25: =COUNTIF(#REF!,$B25)*1/2 | L25: =COUNTIF(#REF!,$B25)*1/3 | M25: =COUNTIF(#REF!,$B25)*3/4 | N25: =COUNTIF(#REF!,$B25)*1/2 | O25: =COUNTIF(#REF!,$B25)*1/3
A26: Aline Eckert | B26: 828268 | E26: 6.5 | F26: 6 | G26: =F26-H26 | H26: =I26-E26 | I26: =SUM(J26:O26) | J26: =SUMIF(#REF!,$B26,#REF!) | K26: =COUNTIF(#REF!,$B26)*1/2 | L26: =COUNTIF(#REF!,$B26)*1/3 | M26: =COUNTIF(#REF!,$B26)*3/4 | N26: =COUNTIF(#REF!,$B26)*1/2 | O26: =COUNTIF(#REF!,$B26)*1/3
A27: Alisha Kilian | B27: 176543 | E27: 0 | F27: 6 | G27: =F27-H27 | H27: =I27-E27 | I27: =SUM(J27:O27) | J27: =SUMIF(#REF!,$B27,#REF!) | K27: =COUNTIF(#REF!,$B27)*1/2 | L27: =COUNTIF(#REF!,$B27)*1/3 | M27: =COUNTIF(#REF!,$B27)*3/4 | N27: =COUNTIF(#REF!,$B27)*1/2 | O27: =COUNTIF(#REF!,$B27)*1/3
A28: Almuth Turré | B28: 542923 | E28: 0 | F28: 6 | G28: =F28-H28 | H28: =I28-E28 | I28: =SUM(J28:O28) | J28: =SUMIF(#REF!,$B28,#REF!) | K28: =COUNTIF(#REF!,$B28)*1/2 | L28: =COUNTIF(#REF!,$B28)*1/3 | M28: =COUNTIF(#REF!,$B28)*3/4 | N28: =COUNTIF(#REF!,$B28)*1/2 | O28: =COUNTIF(#REF!,$B28)*1/3
A29: Amalia Iazzetta | B29: 671569 | C29: BV (alte Regelung, unbefristet 100%) | E29: 0 | F29: 0 | G29: =F29-H29 | H29: =I29-E29 | I29: =SUM(J29:O29) | J29: =SUMIF(#REF!,$B29,#REF!) | K29: =COUNTIF(#REF!,$B29)*1/2 | L29: =COUNTIF(#REF!,$B29)*1/3 | M29: =COUNTIF(#REF!,$B29)*3/4 | N29: =COUNTIF(#REF!,$B29)*1/2 | O29: =COUNTIF(#REF!,$B29)*1/3
A30: Amanda Sims | B30: 617808 | E30: 3 | F30: 6 | G30: =F30-H30 | H30: =I30-E30 | I30: =SUM(J30:O30) | J30: =SUMIF(#REF!,$B30,#REF!) | K30: =COUNTIF(#REF!,$B30)*1/2 | L30: =COUNTIF(#REF!,$B30)*1/3 | M30: =COUNTIF(#REF!,$B30)*3/4 | N30: =COUNTIF(#REF!,$B30)*1/2 | O30: =COUNTIF(#REF!,$B30)*1/3
A31: Amir Hanna | B31: 348165 | D31: 45563 | E31: 1.5 | F31: 6 | G31: =F31-H31 | H31: =I31-E31 | I31: =SUM(J31:O31) | J31: =SUMIF(#REF!,$B31,#REF!) | K31: =COUNTIF(#REF!,$B31)*1/2 | L31: =COUNTIF(#REF!,$B31)*1/3 | M31: =COUNTIF(#REF!,$B31)*3/4 | N31: =COUNTIF(#REF!,$B31)*1/2 | O31: =COUNTIF(#REF!,$B31)*1/3
A32: Amir Negahbani | B32: 438689 | D32: 45961 | E32: 0 | F32: 6 | G32: =F32-H32 | H32: =I32-E32 | I32: =SUM(J32:O32) | J32: =SUMIF(#REF!,$B32,#REF!) | K32: =COUNTIF(#REF!,$B32)*1/2 | L32: =COUNTIF(#REF!,$B32)*1/3 | M32: =COUNTIF(#REF!,$B32)*3/4 | N32: =COUNTIF(#REF!,$B32)*1/2 | O32: =COUNTIF(#REF!,$B32)*1/3
A33: Ana Arroja Romann | B33: 579938 | E33: 7.67 | F33: 6 | G33: =F33-H33 | H33: =I33-E33 | I33: =SUM(J33:O33) | J33: =SUMIF(#REF!,$B33,#REF!) | K33: =COUNTIF(#REF!,$B33)*1/2 | L33: =COUNTIF(#REF!,$B33)*1/3 | M33: =COUNTIF(#REF!,$B33)*3/4 | N33: =COUNTIF(#REF!,$B33)*1/2 | O33: =COUNTIF(#REF!,$B33)*1/3
A34: Andrea Heymann | B34: 479121 | E34: 0 | F34: 6 | G34: =F34-H34 | H34: =I34-E34 | I34: =SUM(J34:O34) | J34: =SUMIF(#REF!,$B34,#REF!) | K34: =COUNTIF(#REF!,$B34)*1/2 | L34: =COUNTIF(#REF!,$B34)*1/3 | M34: =COUNTIF(#REF!,$B34)*3/4 | N34: =COUNTIF(#REF!,$B34)*1/2 | O34: =COUNTIF(#REF!,$B34)*1/3
A35: Andrea Mohr | B35: 299942 | C35: BV (alte Regelung, unbefristet 100%) | E35: 0 | F35: 0 | G35: =F35-H35 | H35: =I35-E35 | I35: =SUM(J35:O35) | J35: =SUMIF(#REF!,$B35,#REF!) | K35: =COUNTIF(#REF!,$B35)*1/2 | L35: =COUNTIF(#REF!,$B35)*1/3 | M35: =COUNTIF(#REF!,$B35)*3/4 | N35: =COUNTIF(#REF!,$B35)*1/2 | O35: =COUNTIF(#REF!,$B35)*1/3
A36: Andrea Morbe | B36: 477377 | E36: 0 | F36: 6 | G36: =F36-H36 | H36: =I36-E36 | I36: =SUM(J36:O36) | J36: =SUMIF(#REF!,$B36,#REF!) | K36: =COUNTIF(#REF!,$B36)*1/2 | L36: =COUNTIF(#REF!,$B36)*1/3 | M36: =COUNTIF(#REF!,$B36)*3/4 | N36: =COUNTIF(#REF!,$B36)*1/2 | O36: =COUNTIF(#REF!,$B36)*1/3
A37: Andrea Straaten | B37: 576311 | E37: 6 | F37: 6 | G37: =F37-H37 | H37: =I37-E37 | I37: =SUM(J37:O37) | J37: =SUMIF(#REF!,$B37,#REF!) | K37: =COUNTIF(#REF!,$B37)*1/2 | L37: =COUNTIF(#REF!,$B37)*1/3 | M37: =COUNTIF(#REF!,$B37)*3/4 | N37: =COUNTIF(#REF!,$B37)*1/2 | O37: =COUNTIF(#REF!,$B37)*1/3
A38: Angela Bilger | B38: 224426 | E38: 16 | F38: 6 | G38: =F38-H38 | H38: =I38-E38 | I38: =SUM(J38:O38) | J38: =SUMIF(#REF!,$B38,#REF!) | K38: =COUNTIF(#REF!,$B38)*1/2 | L38: =COUNTIF(#REF!,$B38)*1/3 | M38: =COUNTIF(#REF!,$B38)*3/4 | N38: =COUNTIF(#REF!,$B38)*1/2 | O38: =COUNTIF(#REF!,$B38)*1/3
A39: Angelique Schubert | B39: 743536 | E39: 1.3333333 | F39: 6 | G39: =F39-H39 | H39: =I39-E39 | I39: =SUM(J39:O39) | J39: =SUMIF(#REF!,$B39,#REF!) | K39: =COUNTIF(#REF!,$B39)*1/2 | L39: =COUNTIF(#REF!,$B39)*1/3 | M39: =COUNTIF(#REF!,$B39)*3/4 | N39: =COUNTIF(#REF!,$B39)*1/2 | O39: =COUNTIF(#REF!,$B39)*1/3
A40: Angelo Fiore | B40: 466403 | E40: 15.67 | F40: 6 | G40: =F40-H40 | H40: =I40-E40 | I40: =SUM(J40:O40) | J40: =SUMIF(#REF!,$B40,#REF!) | K40: =COUNTIF(#REF!,$B40)*1/2 | L40: =COUNTIF(#REF!,$B40)*1/3 | M40: =COUNTIF(#REF!,$B40)*3/4 | N40: =COUNTIF(#REF!,$B40)*1/2 | O40: =COUNTIF(#REF!,$B40)*1/3
...

Sheet Betriebe
A1: Name Betrieb | B1: URL | C1: Kategorie | D1: ID | E1: Januar | F1: Februar | G1: März | H1: April | I1: Mai | J1: Juni | K1: Juli | L1: August | M1: September | N1: Oktober | O1: November | P1: Dezember
A2: Noteinsatz | C2: NP-Betrieb | D2: 1121 | E2: json | F2: json | G2: json | H2: json
A3: Café Tradita | B3: https://foodsharing.de/store/3738 | C3: NP-Betrieb | D3: 3738 | E3: json | F3: json | G3: json | H3: json
A4: Bäckerei Rausch Bornheim | B4: https://foodsharing.de/store/4061 | C4: NP-Betrieb | D4: 4061 | E4: json | F4: json | G4: json | H4: json
A5: Krabbelstube Kullerwiese | B5: https://foodsharing.de/store/4995 | C5: NP-Betrieb | D5: 4995 | E5: json | F5: json | G5: json | H5: json
A6: MokkaTeeria | B6: https://foodsharing.de/store/12483 | C6: NP-Betrieb | D6: 12483 | E6: json | F6: json | G6: json | H6: json
A7: Dein Backhaus (ehem. Billback) | B7: https://foodsharing.de/store/12530 | C7: NP-Betrieb | D7: 12530 | E7: json | F7: json | G7: json | H7: json
A8: Wochenmarkt Bornheim | B8: https://foodsharing.de/store/12984 | C8: NP-Betrieb | D8: 12984 | E8: json | F8: json | G8: json | H8: json
A9: Wochenmarkt Südbahnhof | B9: https://foodsharing.de/store/15150 | C9: NP-Betrieb | D9: 15150 | E9: json | F9: json | G9: json | H9: json
A10: Intermarkt | B10: https://foodsharing.de/store/18561 | C10: NP-Betrieb | D10: 18561 | E10: json | F10: json | G10: json | H10: json
A11: Kaisermarkt Frankfurt (da Bäcker Stand) | B11: https://foodsharing.de/store/18862 | C11: NP-Betrieb | D11: 18862 | E11: json | F11: json | G11: json | H11: json
A12: Wochenmarkt Schillermarkt | B12: https://foodsharing.de/store/21728 | C12: NP-Betrieb | D12: 21728 | E12: json | F12: json | G12: json | H12: json
A13: Vogelsbergbäcker | B13: https://foodsharing.de/store/24590 | C13: NP-Betrieb | D13: 24590 | E13: json | F13: json | G13: json | H13: json
A14: Wochenmarkt Konstablerwache | B14: https://foodsharing.de/store/25330 | C14: NP-Betrieb | D14: 25330 | E14: json | F14: json | G14: json | H14: json
... A22: Fairteiler Bornheim | B22: https://foodsharing.de/store/32714 | C22: Fairteiler | D22: 32714 | E22: json | F22: json | G22: json | H22: json
A23: Zweigstelle Reformhaus Andersch | C23: NP-Betrieb | D23: 32347 | E23: ab Februar 2026 | F23: json | G23: json | H23: json
A24: K&B Bäckerei Schloßstraße | B24: https://foodsharing.de/store/33087 | C24: NP-Betrieb | D24: 33087 | E24: json | F24: json | G24: json | H24: json
A25: Café Frankfurt (Gutleut) | B25: https://foodsharing.de/store/39396 | C25: geschlossen | D25: 39396 | E25: leer | F25: leer | G25: leer | H25: leer
A26: Fairteiler Ada-Kantine | B26: https://foodsharing.de/store/40251 | C26: Fairteiler | D26: 40251 | E26: json | F26: json | G26: json | H26: json
A27: K&B Bäckerei Oeder Weg | B27: https://foodsharing.de/store/34060 | C27: NP-Betrieb | D27: 34060 | E27: json | F27: json | G27: json | H27: json
A28: Quicker ́s Flughafen, Terminal 1 Ankunft A | B28: https://foodsharing.de/store/42641 | C28: geschlossen | D28: 42641 | E28: leer | F28: leer | G28: leer | H28: leer
A29: Quicker ́s Hauptbahnhof | B29: https://foodsharing.de/store/42648 | C29: geschlossen | D29: 42648 | E29: leer | F29: leer | G29: leer | H29: leer
A30: Bäckerei im Scheck in Center Sachsenhausen | B30: https://foodsharing.de/store/41891 | C30: NP-Betrieb | D30: 41891 | E30: json | F30: json | G30: json | H30: json
A31: Bäckerei Cafe BIBI | B31: https://foodsharing.de/store/45407 | C31: NP-Betrieb | D31: 45407 | E31: json | F31: json | G31: json | H31: json
A32: Dünsberg Bäcker auf dem Wochenmarkt in Heddernheim | B32: https://foodsharing.de/store/45984 | C32: NP-Betrieb | D32: 45984 | E32: json | F32: json | G32: json | H32: json
A33: Foodji | C33: NP-Betrieb | D33: 46028 | E33: json | F33: json | G33: json | H33: json
A34: Tegut Kaiserstraße | B34: https://foodsharing.de/store/47643 | C34: NP-Betrieb | D34: 47643 | E34: json | F34: json | G34: json | H34: json
A35: Bäckerei Antika | B35: https://foodsharing.de/store/49255 | C35: NP-Betrieb | D35: 49255 | E35: json | F35: json | G35: json | H35: json
A36: Öffentlichskeitarbeit | B36: https://foodsharing.de/store/52831 | C36: Ö-Arbeit | D36: 52831 | E36: *json | F36: *json | G36: *json
A37: Fairteiler Höchst | B37: https://foodsharing.de/store/53812 | C37: Fairteiler | D37: 53812 | E37: json | F37: json | G37: json | H37: json
A38: Kita Brandhöfchen | B38: https://foodsharing.de/store/50404 | C38: NP-Betrieb | D38: 50404 | E38: json | F38: json | G38: json | H38: json
A39: Fairteiler Schwanheim | B39: https://foodsharing.de/store/57579 | C39: Fairteiler | D39: 57579 | E39: json | F39: json | G39: json | H39: json
A40: Penny Leipziger Straße | B40: https://foodsharing.de/store/50487 | C40: NP-Betrieb | D40: 50487 | E40: json | F40: json | G40: json | H40: json
A41: Penny Bonames | C41: NP-Betrieb | D41: 50480 | I41: NP ab 01.06.2026
A42: Rewe Junker Frankenallee (Gallus) | C42: NP-Betrieb | D42: 51699 | E42: ab Februar 2026 | F42: json | G42: json | H42: json
A43: Rewe Sachsenhausen | B43: https://foodsharing.de/store/57036 | C43: NP-Betrieb | D43: 57036 | E43: json | F43: json | G43: json | H43: json
A44: Steigenberger Airport Hotel - Frankfurt | B44: https://foodsharing.de/store/57673 | C44: NP-Betrieb | D44: 57673 | E44: json | F44: json | G44: json | H44: json
A45: Schul-Catering Konradhof: Carl-von-Weinberg-Schule Goldstein | B45: https://foodsharing.de/store/57964 | C45: NP-Betrieb | D45: 57964 | E45: json | F45: json | G45: json | H45: json
A46: LM-Anlieferung Nachbarschaftstreff „Nebenan“ | B46: https://foodsharing.de/store/59966 | C46: Anlieferung | D46: 59966 | E46: json | F46: json | G46: json | H46: json
A47: Waldstation Supreme Sports Hospitality | B47: https://foodsharing.de/store/58223 | C47: NP-Betrieb | D47: 58223 | E47: json | F47: json | G47: json | H47: json
...

Sheet Farbcodes
A1: Persönliche Gründe
A2: Alter
A3: Erreicht
A4: Posten
A6: Zweitmitglied (nur relevant für 23)

Sheet NP-Betrieb
A1: Titel JSON-Dokument | C1: Datum | D1: ID | E1: Name
A2: 21728_04_2026.json | C2: 2026-04-02T17:15:00+02:00 | D2: 628110 | E2: Monja Rößler
A3: 21728_04_2026.json | C3: 2026-04-02T17:15:00+02:00 | D3: 623731 | E3: Hilke
A4: 21728_04_2026.json | C4: 2026-04-10T17:15:00+02:00 | D4: 442578 | E4: Anna-Catherina Ackermann
A5: 21728_04_2026.json | C5: 2026-04-10T17:15:00+02:00 | D5: 560546 | E5: Irina Evteeva
A6: 21728_04_2026.json | C6: 2026-04-17T17:15:00+02:00 | D6: 797989 | E6: Jennifer Gehrls
A7: 21728_04_2026.json | C7: 2026-04-17T17:15:00+02:00 | D7: 442578 | E7: Anna-Catherina Ackermann
A8: 21728_04_2026.json | C8: 2026-04-24T17:15:00+02:00 | D8: 803118 | E8: Nadine Feldmann
A9: 21728_04_2026.json | C9: 2026-04-24T17:15:00+02:00 | D9: 803535 | E9: Sonja Stamm
A10: 21728_04_2026.json | C10: 2026-04-30T17:15:00+02:00 | D10: 248981 | E10: Alicia Koch
A11: 21728_04_2026.json | C11: 2026-04-30T17:15:00+02:00 | D11: 442578 | E11: Anna-Catherina Ackermann
A12: 58671_04_2026.json | C12: 2026-04-01T20:00:00+02:00 | D12: 872540 | E12: Stefan Becker
A13: 58671_04_2026.json | C13: 2026-04-02T20:00:00+02:00 | D13: 584071 | E13: Caroline
... A2380: 45984_05_2026.json | C2380: 2026-05-29T17:00:00+02:00 | D2380: 476617 | E2380: Manuela Kurze

Sheet Ö-Arbeit
A1: Titel JSON-Dokument | C1: Datum | D1: ID | E1: Name
A2: 52831_04_2026.json | C2: 2026-04-11T10:25:00+02:00 | D2: 479121 | E2: Andrea Heymann
A3: 52831_04_2026.json | C3: 2026-04-11T10:25:00+02:00 | D3: 479121 | E3: Andrea Heymann
A4: 52831_04_2026.json | C4: 2026-04-11T10:30:00+02:00 | D4: 131987 | E4: Simone Beege
A5: 52831_04_2026.json | C5: 2026-04-11T10:30:00+02:00 | D5: 111876 | E5: Ute Fries
A6: 52831_04_2026.json | C6: 2026-04-11T10:30:00+02:00 | D6: 344735 | E6: Jörg Junker
A7: 52831_04_2026.json | C7: 2026-04-11T10:45:00+02:00 | D7: 532833 | E7: Jacqueline Wendt
A8: 52831_04_2026.json | C8: 2026-04-11T10:45:00+02:00 | D8: 806365 | E8: Anne Bürcky
A9: 52831_04_2026.json | C9: 2026-04-11T14:00:00+02:00 | D9: 636064 | E9: Marie Grell
A10: 52831_04_2026.json | C10: 2026-04-11T14:00:00+02:00 | D10: 477377 | E10: Andrea Morbe
A11: 52831_04_2026.json | C11: 2026-04-11T14:00:00+02:00 | D11: 384287 | E11: Fabiola Opitz
A12: 52831_04_2026.json | C12: 2026-04-11T14:00:00+02:00 | D12: 496044 | E12: Katja Hofmaier
A13: 52831_04_2026.json | C13: 2026-04-12T13:45:00+02:00 | D13: 610944 | E13: Sabine Mönkemöller
... A125: 52831_05_2026.json | C125: 2026-05-30T15:00:00+02:00 | D125: 558310 | E125: Florian Schubert

Sheet geschlossen
A1: Titel JSON-Dokument | C1: Datum | D1: ID | E1: Name
A2: 62767_04_2026.json
A3: 42641_04_2026.json
A4: 39396_04_2026.json
A5: 61924_04_2026.json
A6: 42648_04_2026.json
A7: 64376_04_2026.json

Sheet Fairteiler
A1: Titel JSON-Dokument | C1: Datum | D1: ID | E1: Name
A2: 53812_04_2026.json | C2: 2026-04-01T19:00:00+02:00 | D2: 967920 | E2: Marc Burkhard
A3: 66763_04_2026.json | C3: 2026-04-07T18:00:00+02:00 | D3: 833503 | E3: Ermana Ribic
A4: 57579_04_2026.json | C4: 2026-04-01T23:55:00+02:00 | D4: 724884 | E4: Ramona Le
A5: 61227_04_2026.json | C5: 2026-04-02T20:00:00+02:00 | D5: 734566 | E5: Claudia Jakob
A6: 32714_04_2026.json | C6: 2026-04-01T18:45:00+02:00 | D6: 830884 | E6: My-Trinh Ngo
A7: 67344_04_2026.json | C7: 2026-04-04T19:00:00+02:00 | D7: 413594 | E7: Tomke Aljets
A8: 40251_04_2026.json | C8: 2026-04-01T17:00:00+02:00 | D8: 557897 | E8: Alexander Stecher
A9: 65213_04_2026.json | C9: 2026-04-01T16:00:00+02:00 | D9: 832249 | E9: Annika Rummel
A10: 53812_04_2026.json | C10: 2026-04-01T19:00:00+02:00 | D10: 967920 | E10: Marc Burkhard
A11: 53812_04_2026.json | C11: 2026-04-02T19:00:00+02:00 | D11: 926369 | E11: Farah Mahmoud
A12: 53812_04_2026.json | C12: 2026-04-03T19:00:00+02:00 | D12: 440768 | E12: Raisa Khan
A13: 53812_04_2026.json | C13: 2026-04-04T19:00:00+02:00 | D13: 635305 | E13: Marejam Mountij
... A765: 40251_05_2026.json | C765: 2026-05-30T17:00:00+02:00 | D765: 209946 | E765: Gabriele Amekuedi

Sheet Anlieferung
A1: Titel JSON-Dokument | C1: Datum | D1: ID | E1: Name
C2: 2026-04-07T20:00:00+02:00
C3: 2026-04-02T22:00:00+02:00
C5: 2026-04-07T20:00:00+02:00 | D5: 597434 | E5: Anita Lemaile
A6: Anlieferung Do Abend zw. 18 und 22 Uhr | C6: 2026-04-02T22:00:00+02:00 | D6: 703541 | E6: Marit Straub
A7: 59966_04_2026.json | C7: 2026-04-07T20:00:00+02:00 | D7: 597434 | E7: Anita Lemaile
A8: 67643_04_2026.json | C8: 2026-04-02T22:00:00+02:00 | D8: 703541 | E8: Marit Straub
A9: 68127_04_2026.json
A10: 59966_04_2026.json | C10: 2026-04-07T20:00:00+02:00 | D10: 597434 | E10: Anita Lemaile
A11: 59966_04_2026.json | C11: 2026-04-07T20:00:00+02:00 | D11: 829843 | E11: Ute van Beuningen
A12: 59966_04_2026.json | C12: 2026-04-14T20:00:00+02:00 | D12: 914365 | E12: Maria Mokhova
A13: 59966_04_2026.json | C13: 2026-04-14T20:00:00+02:00 | D13: 597434 | E13: Anita Lemaile
A14: 59966_04_2026.json | C14: 2026-04-14T20:00:00+02:00 | D14: 829843 | E14: Ute van Beuningen
A15: 59966_04_2026.json | C15: 2026-04-21T20:00:00+02:00 | D15: 302414 | E15: Monika Hutwelker
A16: 59966_04_2026.json | C16: 2026-04-21T20:00:00+02:00 | D16: 829843 | E16: Ute van Beuningen
A17: 59966_04_2026.json | C17: 2026-04-28T20:00:00+02:00 | D17: 829843 | E17: Ute van Beuningen
A18: 59966_04_2026.json | C18: 2026-04-28T20:00:00+02:00 | D18: 597434 | E18: Anita Lemaile
A19: 59966_04_2026.json | C19: 2026-04-28T20:00:00+02:00 | D19: 266487 | E19: Florian Schöniger
A20: 67643_04_2026.json | C20: 2026-04-02T22:00:00+02:00 | D20: 703541 | E20: Marit Straub
A21: 67643_04_2026.json | C21: 2026-04-02T22:00:00+02:00 | D21: 967920 | E21: Marc Burkhard
... A84: 67643_05_2026.json | C84: 2026-05-28T22:00:00+02:00 | D84: 789902 | E84: Maja Krawczyk-Sünder
