Workbook
Name ExterneDaten_1_1: 0
Name ExterneDaten_1_10: 0
Name ExterneDaten_1_11: 0
Name ExterneDaten_1_12: 0
Name ExterneDaten_1_13: 0
Name ExterneDaten_1_2: 0
Name ExterneDaten_1_3: 0
Name ExterneDaten_1_4: 0
Name ExterneDaten_1_5: 0
Name ExterneDaten_1_6: 0
Name ExterneDaten_1_7: 0
Name ExterneDaten_1_8: 0
Name ExterneDaten_1_9: 0

Sheet offen_aus_25
A1: Name | B1: ID | C1: Befreit? | D1: Offene Stunden aus 25 (bis 31.12.2025) | E1: Stunden ab 26 | F1: noch immer offene Stunden nach Ausgleich
A2: Abdelouahed El Haddoui | B2: 826067 | D2: 0 | E2: =VLOOKUP(B2,Gesamtstunden_26!B:I,8,0) -> 1.3333333 | F2: =D2-E2 -> -1.3333333
A3: Adelheid Henrich | B3: 136454 | D3: 3.3333333 | E3: =VLOOKUP(B3,Gesamtstunden_26!B:I,8,0) -> 1.6666667 | F3: =D3-E3 -> 1.6666667
A4: Adrian Deptuch | B4: 216555 | D4: 4.6733333 | E4: =VLOOKUP(B4,Gesamtstunden_26!B:I,8,0) -> 1.6666667 | F4: =D4-E4 -> 3.0066667
A5: Adrian Rölver | B5: 298763 | D5: 5.6666667 | E5: =VLOOKUP(B5,Gesamtstunden_26!B:I,8,0) -> 0.66666667 | F5: =D5-E5 -> 5
A6: Aicha Boutasfat | B6: 276971 | D6: 0 | E6: =VLOOKUP(B6,Gesamtstunden_26!B:I,8,0) -> 0.33333333 | F6: =D6-E6 -> -0.33333333
A7: Aileen Taschner | B7: 214380 | D7: 0 | E7: =VLOOKUP(B7,Gesamtstunden_26!B:I,8,0) -> 0 | F7: =D7-E7 -> 0
A8: Alberto Kästner Fritsch | B8: 794748 | D8: 3 | E8: =VLOOKUP(B8,Gesamtstunden_26!B:I,8,0) -> 0 | F8: =D8-E8 -> 3
A9: Aleksandra Aleksic-Bardjesteh | B9: 662108 | D9: 0 | E9: =VLOOKUP(B9,Gesamtstunden_26!B:I,8,0) -> 0 | F9: =D9-E9 -> 0
A10: Alena Klein | B10: 742934 | D10: 14 | E10: =VLOOKUP(B10,Gesamtstunden_26!B:I,8,0) -> 0 | F10: =D10-E10 -> 14
A11: Alena Korbut | B11: 509374 | D11: 0 | E11: =VLOOKUP(B11,Gesamtstunden_26!B:I,8,0) -> 3.5 | F11: =D11-E11 -> -3.5
A12: Alexander Epp | B12: 703098 | D12: 9.1666667 | E12: =VLOOKUP(B12,Gesamtstunden_26!B:I,8,0) -> 0.66666667 | F12: =D12-E12 -> 8.5
A13: Alexander Roppelt | B13: 720432 | D13: 0.33333333 | E13: =VLOOKUP(B13,Gesamtstunden_26!B:I,8,0) -> 1.6666667 | F13: =D13-E13 -> -1.3333333
... A814: Zacharias Funk | B814: 746046 | D814: 0 | E814: =VLOOKUP(B814,Gesamtstunden_26!B:I,8,0) -> 1 | F814: =D814-E814 -> -1

Sheet Gesamtstunden_26
A1: Name | B1: ID | C1: Befreit? | D1: Vereinseintritt | E1: Offene Stunden aus 25 | F1: Soll-Stunden für 26 | G1: Offene Stunden für 26 | H1: für 26 zählende Stunden | I1: Gesamtstunden (in 26 geleistet) | J1: Öffentlichkeitsarbeit | K1: Fairteilerreinigung | L1: Abholung Nicht-Premium | M1: Fairteilungen (z.B. Friedensgemeinde) | N1: Anlieferung (z.B. Friedensgemeinde) | O1: Probeabholungen
A2: Abdelouahed El Haddoui | B2: 826067 | E2: 0 | F2: 6 | G2: =F2-H2 -> 4.6666667 | H2: =I2-E2 -> 1.3333333 | I2: =SUM(J2:O2) -> 1.3333333 | J2: =SUMIF(Oeffentlichkeitsarbeit!$D:$D,$B2,Oeffentlichkeitsarbeit!$F:$F) -> 0 | K2: =COUNTIF(Fairteiler!$D:$D,$B2)*1/2 -> 0 | L2: =COUNTIF('NP-Betrieb'!D:D,$B2)*1/3 -> 1.3333333 | M2: =COUNTIF(Fairteilungen!$D:$D,$B2)*3/4 -> 0 | N2: =COUNTIF(Anlieferung!D:D,$B2)*1/2 -> 0 | O2: =COUNTIF(Probeabholungen!B:B,$B2)*1/3 -> 0
A3: Adelheid Henrich | B3: 136454 | E3: 3.3333333 | F3: 6 | G3: =F3-H3 -> 7.6666667 | H3: =I3-E3 -> -1.6666667 | I3: =SUM(J3:O3) -> 1.6666667 | J3: =SUMIF(Oeffentlichkeitsarbeit!$D:$D,$B3,Oeffentlichkeitsarbeit!$F:$F) -> 0 | K3: =COUNTIF(Fairteiler!$D:$D,$B3)*1/2 -> 0 | L3: =COUNTIF('NP-Betrieb'!D:D,$B3)*1/3 -> 1.6666667 | M3: =COUNTIF(Fairteilungen!$D:$D,$B3)*3/4 -> 0 | N3: =COUNTIF(Anlieferung!D:D,$B3)*1/2 -> 0 | O3: =COUNTIF(Probeabholungen!B:B,$B3)*1/3 -> 0
A4: Adrian Deptuch | B4: 216555 | E4: 4.6733333 | F4: 6 | G4: =F4-H4 -> 9.0066667 | H4: =I4-E4 -> -3.0066667 | I4: =SUM(J4:O4) -> 1.6666667 | J4: =SUMIF(Oeffentlichkeitsarbeit!$D:$D,$B4,Oeffentlichkeitsarbeit!$F:$F) -> 0 | K4: =COUNTIF(Fairteiler!$D:$D,$B4)*1/2 -> 0 | L4: =COUNTIF('NP-Betrieb'!D:D,$B4)*1/3 -> 1.6666667 | M4: =COUNTIF(Fairteilungen!$D:$D,$B4)*3/4 -> 0 | N4: =COUNTIF(Anlieferung!D:D,$B4)*1/2 -> 0 | O4: =COUNTIF(Probeabholungen!B:B,$B4)*1/3 -> 0
A5: Adrian Rölver | B5: 298763 | E5: 5.6666667 | F5: 6 | G5: =F5-H5 -> 11 | H5: =I5-E5 -> -5 | I5: =SUM(J5:O5) -> 0.66666667 | J5: =SUMIF(Oeffentlichkeitsarbeit!$D:$D,$B5,Oeffentlichkeitsarbeit!$F:$F) -> 0 | K5: =COUNTIF(Fairteiler!$D:$D,$B5)*1/2 -> 0 | L5: =COUNTIF('NP-Betrieb'!D:D,$B5)*1/3 -> 0.66666667 | M5: =COUNTIF(Fairteilungen!$D:$D,$B5)*3/4 -> 0 | N5: =COUNTIF(Anlieferung!D:D,$B5)*1/2 -> 0 | O5: =COUNTIF(Probeabholungen!B:B,$B5)*1/3 -> 0
A6: Aicha Boutasfat | B6: 276971 | C6: BV (alte Regelung, unbefristet 100%) | E6: 0 | F6: 0 | G6: =F6-H6 -> -0.33333333 | H6: =I6-E6 -> 0.33333333 | I6: =SUM(J6:O6) -> 0.33333333 | J6: =SUMIF(Oeffentlichkeitsarbeit!$D:$D,$B6,Oeffentlichkeitsarbeit!$F:$F) -> 0 | K6: =COUNTIF(Fairteiler!$D:$D,$B6)*1/2 -> 0 | L6: =COUNTIF('NP-Betrieb'!D:D,$B6)*1/3 -> 0.33333333 | M6: =COUNTIF(Fairteilungen!$D:$D,$B6)*3/4 -> 0 | N6: =COUNTIF(Anlieferung!D:D,$B6)*1/2 -> 0 | O6: =COUNTIF(Probeabholungen!B:B,$B6)*1/3 -> 0
A7: Aileen Taschner | B7: 214380 | E7: 0 | F7: 6 | G7: =F7-H7 -> 6 | H7: =I7-E7 -> 0 | I7: =SUM(J7:O7) -> 0 | J7: =SUMIF(Oeffentlichkeitsarbeit!$D:$D,$B7,Oeffentlichkeitsarbeit!$F:$F) -> 0 | K7: =COUNTIF(Fairteiler!$D:$D,$B7)*1/2 -> 0 | L7: =COUNTIF('NP-Betrieb'!D:D,$B7)*1/3 -> 0 | M7: =COUNTIF(Fairteilungen!$D:$D,$B7)*3/4 -> 0 | N7: =COUNTIF(Anlieferung!D:D,$B7)*1/2 -> 0 | O7: =COUNTIF(Probeabholungen!B:B,$B7)*1/3 -> 0
A8: Alberto Kästner Fritsch | B8: 794748 | D8: 45845 | E8: 3 | F8: 6 | G8: =F8-H8 -> 9 | H8: =I8-E8 -> -3 | I8: =SUM(J8:O8) -> 0 | J8: =SUMIF(Oeffentlichkeitsarbeit!$D:$D,$B8,Oeffentlichkeitsarbeit!$F:$F) -> 0 | K8: =COUNTIF(Fairteiler!$D:$D,$B8)*1/2 -> 0 | L8: =COUNTIF('NP-Betrieb'!D:D,$B8)*1/3 -> 0 | M8: =COUNTIF(Fairteilungen!$D:$D,$B8)*3/4 -> 0 | N8: =COUNTIF(Anlieferung!D:D,$B8)*1/2 -> 0 | O8: =COUNTIF(Probeabholungen!B:B,$B8)*1/3 -> 0
A9: Aleksandra Aleksic-Bardjesteh | B9: 662108 | D9: 45228 | E9: 0 | F9: 6 | G9: =F9-H9 -> 6 | H9: =I9-E9 -> 0 | I9: =SUM(J9:O9) -> 0 | J9: =SUMIF(Oeffentlichkeitsarbeit!$D:$D,$B9,Oeffentlichkeitsarbeit!$F:$F) -> 0 | K9: =COUNTIF(Fairteiler!$D:$D,$B9)*1/2 -> 0 | L9: =COUNTIF('NP-Betrieb'!D:D,$B9)*1/3 -> 0 | M9: =COUNTIF(Fairteilungen!$D:$D,$B9)*3/4 -> 0 | N9: =COUNTIF(Anlieferung!D:D,$B9)*1/2 -> 0 | O9: =COUNTIF(Probeabholungen!B:B,$B9)*1/3 -> 0
A10: Alena Klein | B10: 742934 | D10: 45097 | E10: 14 | F10: 6 | G10: =F10-H10 -> 20 | H10: =I10-E10 -> -14 | I10: =SUM(J10:O10) -> 0 | J10: =SUMIF(Oeffentlichkeitsarbeit!$D:$D,$B10,Oeffentlichkeitsarbeit!$F:$F) -> 0 | K10: =COUNTIF(Fairteiler!$D:$D,$B10)*1/2 -> 0 | L10: =COUNTIF('NP-Betrieb'!D:D,$B10)*1/3 -> 0 | M10: =COUNTIF(Fairteilungen!$D:$D,$B10)*3/4 -> 0 | N10: =COUNTIF(Anlieferung!D:D,$B10)*1/2 -> 0 | O10: =COUNTIF(Probeabholungen!B:B,$B10)*1/3 -> 0
A11: Alena Korbut | B11: 509374 | E11: 0 | F11: 6 | G11: =F11-H11 -> 2.5 | H11: =I11-E11 -> 3.5 | I11: =SUM(J11:O11) -> 3.5 | J11: =SUMIF(Oeffentlichkeitsarbeit!$D:$D,$B11,Oeffentlichkeitsarbeit!$F:$F) -> 0 | K11: =COUNTIF(Fairteiler!$D:$D,$B11)*1/2 -> 3.5 | L11: =COUNTIF('NP-Betrieb'!D:D,$B11)*1/3 -> 0 | M11: =COUNTIF(Fairteilungen!$D:$D,$B11)*3/4 -> 0 | N11: =COUNTIF(Anlieferung!D:D,$B11)*1/2 -> 0 | O11: =COUNTIF(Probeabholungen!B:B,$B11)*1/3 -> 0
A12: Alexander Epp | B12: 703098 | D12: 45058 | E12: 9.1666667 | F12: 6 | G12: =F12-H12 -> 14.5 | H12: =I12-E12 -> -8.5 | I12: =SUM(J12:O12) -> 0.66666667 | J12: =SUMIF(Oeffentlichkeitsarbeit!$D:$D,$B12,Oeffentlichkeitsarbeit!$F:$F) -> 0 | K12: =COUNTIF(Fairteiler!$D:$D,$B12)*1/2 -> 0 | L12: =COUNTIF('NP-Betrieb'!D:D,$B12)*1/3 -> 0.66666667 | M12: =COUNTIF(Fairteilungen!$D:$D,$B12)*3/4 -> 0 | N12: =COUNTIF(Anlieferung!D:D,$B12)*1/2 -> 0 | O12: =COUNTIF(Probeabholungen!B:B,$B12)*1/3 -> 0
A13: Alexander Roppelt | B13: 720432 | D13: 45061 | E13: 0.33333333 | F13: 6 | G13: =F13-H13 -> 4.6666667 | H13: =I13-E13 -> 1.3333333 | I13: =SUM(J13:O13) -> 1.6666667 | J13: =SUMIF(Oeffentlichkeitsarbeit!$D:$D,$B13,Oeffentlichkeitsarbeit!$F:$F) -> 0 | K13: =COUNTIF(Fairteiler!$D:$D,$B13)*1/2 -> 0 | L13: =COUNTIF('NP-Betrieb'!D:D,$B13)*1/3 -> 1.6666667 | M13: =COUNTIF(Fairteilungen!$D:$D,$B13)*3/4 -> 0 | N13: =COUNTIF(Anlieferung!D:D,$B13)*1/2 -> 0 | O13: =COUNTIF(Probeabholungen!B:B,$B13)*1/3 -> 0
A14: Alexander Stecher | B14: 557897 | E14: 0 | F14: 6 | G14: =F14-H14 -> -4.6666667 | H14: =I14-E14 -> 10.666667 | I14: =SUM(J14:O14) -> 10.666667 | J14: =SUMIF(Oeffentlichkeitsarbeit!$D:$D,$B14,Oeffentlichkeitsarbeit!$F:$F) -> 0 | K14: =COUNTIF(Fairteiler!$D:$D,$B14)*1/2 -> 4 | L14: =COUNTIF('NP-Betrieb'!D:D,$B14)*1/3 -> 6.6666667 | M14: =COUNTIF(Fairteilungen!$D:$D,$B14)*3/4 -> 0 | N14: =COUNTIF(Anlieferung!D:D,$B14)*1/2 -> 0 | O14: =COUNTIF(Probeabholungen!B:B,$B14)*1/3 -> 0
A15: Alexander Vainshtein | B15: 871845 | D15: 45612 | E15: 0 | F15: 6 | G15: =F15-H15 -> 2.6666667 | H15: =I15-E15 -> 3.3333333 | I15: =SUM(J15:O15) -> 3.3333333 | J15: =SUMIF(Oeffentlichkeitsarbeit!$D:$D,$B15,Oeffentlichkeitsarbeit!$F:$F) -> 0 | K15: =COUNTIF(Fairteiler!$D:$D,$B15)*1/2 -> 0 | L15: =COUNTIF('NP-Betrieb'!D:D,$B15)*1/3 -> 3.3333333 | M15: =COUNTIF(Fairteilungen!$D:$D,$B15)*3/4 -> 0 | N15: =COUNTIF(Anlieferung!D:D,$B15)*1/2 -> 0 | O15: =COUNTIF(Probeabholungen!B:B,$B15)*1/3 -> 0
A16: Alexandra Arend | B16: 643035 | E16: 5.3333333 | F16: 6 | G16: =F16-H16 -> 11.333333 | H16: =I16-E16 -> -5.3333333 | I16: =SUM(J16:O16) -> 0 | J16: =SUMIF(Oeffentlichkeitsarbeit!$D:$D,$B16,Oeffentlichkeitsarbeit!$F:$F) -> 0 | K16: =COUNTIF(Fairteiler!$D:$D,$B16)*1/2 -> 0 | L16: =COUNTIF('NP-Betrieb'!D:D,$B16)*1/3 -> 0 | M16: =COUNTIF(Fairteilungen!$D:$D,$B16)*3/4 -> 0 | N16: =COUNTIF(Anlieferung!D:D,$B16)*1/2 -> 0 | O16: =COUNTIF(Probeabholungen!B:B,$B16)*1/3 -> 0
A17: Alexandra Jansen | B17: 654688 | C17: GdB 50 | E17: 0 | F17: 0 | G17: =F17-H17 -> 0 | H17: =I17-E17 -> 0 | I17: =SUM(J17:O17) -> 0 | J17: =SUMIF(Oeffentlichkeitsarbeit!$D:$D,$B17,Oeffentlichkeitsarbeit!$F:$F) -> 0 | K17: =COUNTIF(Fairteiler!$D:$D,$B17)*1/2 -> 0 | L17: =COUNTIF('NP-Betrieb'!D:D,$B17)*1/3 -> 0 | M17: =COUNTIF(Fairteilungen!$D:$D,$B17)*3/4 -> 0 | N17: =COUNTIF(Anlieferung!D:D,$B17)*1/2 -> 0 | O17: =COUNTIF(Probeabholungen!B:B,$B17)*1/3 -> 0
A18: Alexandra Päzolt | B18: 964211 | D18: 45985 | E18: 0 | F18: 6 | G18: =F18-H18 -> -3.6666667 | H18: =I18-E18 -> 9.6666667 | I18: =SUM(J18:O18) -> 9.6666667 | J18: =SUMIF(Oeffentlichkeitsarbeit!$D:$D,$B18,Oeffentlichkeitsarbeit!$F:$F) -> 0 | K18: =COUNTIF(Fairteiler!$D:$D,$B18)*1/2 -> 0 | L18: =COUNTIF('NP-Betrieb'!D:D,$B18)*1/3 -> 9.6666667 | M18: =COUNTIF(Fairteilungen!$D:$D,$B18)*3/4 -> 0 | N18: =COUNTIF(Anlieferung!D:D,$B18)*1/2 -> 0 | O18: =COUNTIF(Probeabholungen!B:B,$B18)*1/3 -> 0
A19: Ali Kabouch | B19: 597806 | E19: 0 | F19: 6 | G19: =F19-H19 -> 4.6666667 | H19: =I19-E19 -> 1.3333333 | I19: =SUM(J19:O19) -> 1.3333333 | J19: =SUMIF(Oeffentlichkeitsarbeit!$D:$D,$B19,Oeffentlichkeitsarbeit!$F:$F) -> 0 | K19: =COUNTIF(Fairteiler!$D:$D,$B19)*1/2 -> 0 | L19: =COUNTIF('NP-Betrieb'!D:D,$B19)*1/3 -> 1.3333333 | M19: =COUNTIF(Fairteilungen!$D:$D,$B19)*3/4 -> 0 | N19: =COUNTIF(Anlieferung!D:D,$B19)*1/2 -> 0 | O19: =COUNTIF(Probeabholungen!B:B,$B19)*1/3 -> 0
A20: Alicia Artschwager | B20: 565142 | E20: 0 | F20: 6 | G20: =F20-H20 -> 3.6666667 | H20: =I20-E20 -> 2.3333333 | I20: =SUM(J20:O20) -> 2.3333333 | J20: =SUMIF(Oeffentlichkeitsarbeit!$D:$D,$B20,Oeffentlichkeitsarbeit!$F:$F) -> 0 | K20: =COUNTIF(Fairteiler!$D:$D,$B20)*1/2 -> 2 | L20: =COUNTIF('NP-Betrieb'!D:D,$B20)*1/3 -> 0.33333333 | M20: =COUNTIF(Fairteilungen!$D:$D,$B20)*3/4 -> 0 | N20: =COUNTIF(Anlieferung!D:D,$B20)*1/2 -> 0 | O20: =COUNTIF(Probeabholungen!B:B,$B20)*1/3 -> 0
A21: Alicia Koch | B21: 248981 | C21: Alter | E21: 0 | F21: 0 | G21: =F21-H21 -> -5 | H21: =I21-E21 -> 5 | I21: =SUM(J21:O21) -> 5 | J21: =SUMIF(Oeffentlichkeitsarbeit!$D:$D,$B21,Oeffentlichkeitsarbeit!$F:$F) -> 0 | K21: =COUNTIF(Fairteiler!$D:$D,$B21)*1/2 -> 0 | L21: =COUNTIF('NP-Betrieb'!D:D,$B21)*1/3 -> 3 | M21: =COUNTIF(Fairteilungen!$D:$D,$B21)*3/4 -> 0 | N21: =COUNTIF(Anlieferung!D:D,$B21)*1/2 -> 0 | O21: =COUNTIF(Probeabholungen!B:B,$B21)*1/3 -> 2
A22: Alicia Mohn | B22: 617287 | E22: 12 | F22: 6 | G22: =F22-H22 -> 18 | H22: =I22-E22 -> -12 | I22: =SUM(J22:O22) -> 0 | J22: =SUMIF(Oeffentlichkeitsarbeit!$D:$D,$B22,Oeffentlichkeitsarbeit!$F:$F) -> 0 | K22: =COUNTIF(Fairteiler!$D:$D,$B22)*1/2 -> 0 | L22: =COUNTIF('NP-Betrieb'!D:D,$B22)*1/3 -> 0 | M22: =COUNTIF(Fairteilungen!$D:$D,$B22)*3/4 -> 0 | N22: =COUNTIF(Anlieferung!D:D,$B22)*1/2 -> 0 | O22: =COUNTIF(Probeabholungen!B:B,$B22)*1/3 -> 0
A23: Alicia Schrader | B23: 805780 | D23: 45531 | E23: 6.6666667 | F23: 6 | G23: =F23-H23 -> 12.666667 | H23: =I23-E23 -> -6.6666667 | I23: =SUM(J23:O23) -> 0 | J23: =SUMIF(Oeffentlichkeitsarbeit!$D:$D,$B23,Oeffentlichkeitsarbeit!$F:$F) -> 0 | K23: =COUNTIF(Fairteiler!$D:$D,$B23)*1/2 -> 0 | L23: =COUNTIF('NP-Betrieb'!D:D,$B23)*1/3 -> 0 | M23: =COUNTIF(Fairteilungen!$D:$D,$B23)*3/4 -> 0 | N23: =COUNTIF(Anlieferung!D:D,$B23)*1/2 -> 0 | O23: =COUNTIF(Probeabholungen!B:B,$B23)*1/3 -> 0
A24: Alina Braun | B24: 480180 | D24: 45171 | E24: 0 | F24: 6 | G24: =F24-H24 -> 5.6666667 | H24: =I24-E24 -> 0.33333333 | I24: =SUM(J24:O24) -> 0.33333333 | J24: =SUMIF(Oeffentlichkeitsarbeit!$D:$D,$B24,Oeffentlichkeitsarbeit!$F:$F) -> 0 | K24: =COUNTIF(Fairteiler!$D:$D,$B24)*1/2 -> 0 | L24: =COUNTIF('NP-Betrieb'!D:D,$B24)*1/3 -> 0.33333333 | M24: =COUNTIF(Fairteilungen!$D:$D,$B24)*3/4 -> 0 | N24: =COUNTIF(Anlieferung!D:D,$B24)*1/2 -> 0 | O24: =COUNTIF(Probeabholungen!B:B,$B24)*1/3 -> 0
A25: Alina Panzenböck | B25: 486886 | D25: 45845 | E25: 3 | F25: 6 | G25: =F25-H25 -> -0.66666667 | H25: =I25-E25 -> 6.6666667 | I25: =SUM(J25:O25) -> 9.6666667 | J25: =SUMIF(Oeffentlichkeitsarbeit!$D:$D,$B25,Oeffentlichkeitsarbeit!$F:$F) -> 7 | K25: =COUNTIF(Fairteiler!$D:$D,$B25)*1/2 -> 0 | L25: =COUNTIF('NP-Betrieb'!D:D,$B25)*1/3 -> 2.6666667 | M25: =COUNTIF(Fairteilungen!$D:$D,$B25)*3/4 -> 0 | N25: =COUNTIF(Anlieferung!D:D,$B25)*1/2 -> 0 | O25: =COUNTIF(Probeabholungen!B:B,$B25)*1/3 -> 0
A26: Aline Eckert | B26: 828268 | E26: 6.5 | F26: 6 | G26: =F26-H26 -> 1.3333333 | H26: =I26-E26 -> 4.6666667 | I26: =SUM(J26:O26) -> 11.166667 | J26: =SUMIF(Oeffentlichkeitsarbeit!$D:$D,$B26,Oeffentlichkeitsarbeit!$F:$F) -> 0 | K26: =COUNTIF(Fairteiler!$D:$D,$B26)*1/2 -> 4.5 | L26: =COUNTIF('NP-Betrieb'!D:D,$B26)*1/3 -> 6.6666667 | M26: =COUNTIF(Fairteilungen!$D:$D,$B26)*3/4 -> 0 | N26: =COUNTIF(Anlieferung!D:D,$B26)*1/2 -> 0 | O26: =COUNTIF(Probeabholungen!B:B,$B26)*1/3 -> 0
A27: Alisha Kilian | B27: 176543 | E27: 0 | F27: 6 | G27: =F27-H27 -> 6 | H27: =I27-E27 -> 0 | I27: =SUM(J27:O27) -> 0 | J27: =SUMIF(Oeffentlichkeitsarbeit!$D:$D,$B27,Oeffentlichkeitsarbeit!$F:$F) -> 0 | K27: =COUNTIF(Fairteiler!$D:$D,$B27)*1/2 -> 0 | L27: =COUNTIF('NP-Betrieb'!D:D,$B27)*1/3 -> 0 | M27: =COUNTIF(Fairteilungen!$D:$D,$B27)*3/4 -> 0 | N27: =COUNTIF(Anlieferung!D:D,$B27)*1/2 -> 0 | O27: =COUNTIF(Probeabholungen!B:B,$B27)*1/3 -> 0
A28: Almuth Turré | B28: 542923 | E28: 0 | F28: 6 | G28: =F28-H28 -> -5.6666667 | H28: =I28-E28 -> 11.666667 | I28: =SUM(J28:O28) -> 11.666667 | J28: =SUMIF(Oeffentlichkeitsarbeit!$D:$D,$B28,Oeffentlichkeitsarbeit!$F:$F) -> 0 | K28: =COUNTIF(Fairteiler!$D:$D,$B28)*1/2 -> 0 | L28: =COUNTIF('NP-Betrieb'!D:D,$B28)*1/3 -> 11.666667 | M28: =COUNTIF(Fairteilungen!$D:$D,$B28)*3/4 -> 0 | N28: =COUNTIF(Anlieferung!D:D,$B28)*1/2 -> 0 | O28: =COUNTIF(Probeabholungen!B:B,$B28)*1/3 -> 0
A29: Amalia Iazzetta | B29: 671569 | C29: BV (alte Regelung, unbefristet 100%) | E29: 0 | F29: 0 | G29: =F29-H29 -> -0.33333333 | H29: =I29-E29 -> 0.33333333 | I29: =SUM(J29:O29) -> 0.33333333 | J29: =SUMIF(Oeffentlichkeitsarbeit!$D:$D,$B29,Oeffentlichkeitsarbeit!$F:$F) -> 0 | K29: =COUNTIF(Fairteiler!$D:$D,$B29)*1/2 -> 0 | L29: =COUNTIF('NP-Betrieb'!D:D,$B29)*1/3 -> 0.33333333 | M29: =COUNTIF(Fairteilungen!$D:$D,$B29)*3/4 -> 0 | N29: =COUNTIF(Anlieferung!D:D,$B29)*1/2 -> 0 | O29: =COUNTIF(Probeabholungen!B:B,$B29)*1/3 -> 0
A30: Amanda Sims | B30: 617808 | E30: 3 | F30: 6 | G30: =F30-H30 -> 3 | H30: =I30-E30 -> 3 | I30: =SUM(J30:O30) -> 6 | J30: =SUMIF(Oeffentlichkeitsarbeit!$D:$D,$B30,Oeffentlichkeitsarbeit!$F:$F) -> 0 | K30: =COUNTIF(Fairteiler!$D:$D,$B30)*1/2 -> 0 | L30: =COUNTIF('NP-Betrieb'!D:D,$B30)*1/3 -> 6 | M30: =COUNTIF(Fairteilungen!$D:$D,$B30)*3/4 -> 0 | N30: =COUNTIF(Anlieferung!D:D,$B30)*1/2 -> 0 | O30: =COUNTIF(Probeabholungen!B:B,$B30)*1/3 -> 0
A31: Amir Hanna | B31: 348165 | D31: 45563 | E31: 1.5 | F31: 6 | G31: =F31-H31 -> 5.5 | H31: =I31-E31 -> 0.5 | I31: =SUM(J31:O31) -> 2 | J31: =SUMIF(Oeffentlichkeitsarbeit!$D:$D,$B31,Oeffentlichkeitsarbeit!$F:$F) -> 0 | K31: =COUNTIF(Fairteiler!$D:$D,$B31)*1/2 -> 0 | L31: =COUNTIF('NP-Betrieb'!D:D,$B31)*1/3 -> 2 | M31: =COUNTIF(Fairteilungen!$D:$D,$B31)*3/4 -> 0 | N31: =COUNTIF(Anlieferung!D:D,$B31)*1/2 -> 0 | O31: =COUNTIF(Probeabholungen!B:B,$B31)*1/3 -> 0
A32: Amir Negahbani | B32: 438689 | D32: 45961 | E32: 0 | F32: 6 | G32: =F32-H32 -> 3.6666667 | H32: =I32-E32 -> 2.3333333 | I32: =SUM(J32:O32) -> 2.3333333 | J32: =SUMIF(Oeffentlichkeitsarbeit!$D:$D,$B32,Oeffentlichkeitsarbeit!$F:$F) -> 0 | K32: =COUNTIF(Fairteiler!$D:$D,$B32)*1/2 -> 0 | L32: =COUNTIF('NP-Betrieb'!D:D,$B32)*1/3 -> 2.3333333 | M32: =COUNTIF(Fairteilungen!$D:$D,$B32)*3/4 -> 0 | N32: =COUNTIF(Anlieferung!D:D,$B32)*1/2 -> 0 | O32: =COUNTIF(Probeabholungen!B:B,$B32)*1/3 -> 0
A33: Ana Arroja Romann | B33: 579938 | E33: 7.67 | F33: 6 | G33: =F33-H33 -> 13.67 | H33: =I33-E33 -> -7.67 | I33: =SUM(J33:O33) -> 0 | J33: =SUMIF(Oeffentlichkeitsarbeit!$D:$D,$B33,Oeffentlichkeitsarbeit!$F:$F) -> 0 | K33: =COUNTIF(Fairteiler!$D:$D,$B33)*1/2 -> 0 | L33: =COUNTIF('NP-Betrieb'!D:D,$B33)*1/3 -> 0 | M33: =COUNTIF(Fairteilungen!$D:$D,$B33)*3/4 -> 0 | N33: =COUNTIF(Anlieferung!D:D,$B33)*1/2 -> 0 | O33: =COUNTIF(Probeabholungen!B:B,$B33)*1/3 -> 0
A34: Andrea Heymann | B34: 479121 | E34: 0 | F34: 6 | G34: =F34-H34 -> -1.1666667 | H34: =I34-E34 -> 7.1666667 | I34: =SUM(J34:O34) -> 7.1666667 | J34: =SUMIF(Oeffentlichkeitsarbeit!$D:$D,$B34,Oeffentlichkeitsarbeit!$F:$F) -> 1.5 | K34: =COUNTIF(Fairteiler!$D:$D,$B34)*1/2 -> 0 | L34: =COUNTIF('NP-Betrieb'!D:D,$B34)*1/3 -> 4.6666667 | M34: =COUNTIF(Fairteilungen!$D:$D,$B34)*3/4 -> 0 | N34: =COUNTIF(Anlieferung!D:D,$B34)*1/2 -> 0 | O34: =COUNTIF(Probeabholungen!B:B,$B34)*1/3 -> 1
A35: Andrea Mohr | B35: 299942 | C35: BV (alte Regelung, unbefristet 100%) | E35: 0 | F35: 0 | G35: =F35-H35 -> -1 | H35: =I35-E35 -> 1 | I35: =SUM(J35:O35) -> 1 | J35: =SUMIF(Oeffentlichkeitsarbeit!$D:$D,$B35,Oeffentlichkeitsarbeit!$F:$F) -> 0 | K35: =COUNTIF(Fairteiler!$D:$D,$B35)*1/2 -> 0 | L35: =COUNTIF('NP-Betrieb'!D:D,$B35)*1/3 -> 1 | M35: =COUNTIF(Fairteilungen!$D:$D,$B35)*3/4 -> 0 | N35: =COUNTIF(Anlieferung!D:D,$B35)*1/2 -> 0 | O35: =COUNTIF(Probeabholungen!B:B,$B35)*1/3 -> 0
A36: Andrea Morbe | B36: 477377 | E36: 0 | F36: 6 | G36: =F36-H36 -> 3.3333333 | H36: =I36-E36 -> 2.6666667 | I36: =SUM(J36:O36) -> 2.6666667 | J36: =SUMIF(Oeffentlichkeitsarbeit!$D:$D,$B36,Oeffentlichkeitsarbeit!$F:$F) -> 0 | K36: =COUNTIF(Fairteiler!$D:$D,$B36)*1/2 -> 0 | L36: =COUNTIF('NP-Betrieb'!D:D,$B36)*1/3 -> 2.6666667 | M36: =COUNTIF(Fairteilungen!$D:$D,$B36)*3/4 -> 0 | N36: =COUNTIF(Anlieferung!D:D,$B36)*1/2 -> 0 | O36: =COUNTIF(Probeabholungen!B:B,$B36)*1/3 -> 0
A37: Andrea Straaten | B37: 576311 | E37: 6 | F37: 6 | G37: =F37-H37 -> 12 | H37: =I37-E37 -> -6 | I37: =SUM(J37:O37) -> 0 | J37: =SUMIF(Oeffentlichkeitsarbeit!$D:$D,$B37,Oeffentlichkeitsarbeit!$F:$F) -> 0 | K37: =COUNTIF(Fairteiler!$D:$D,$B37)*1/2 -> 0 | L37: =COUNTIF('NP-Betrieb'!D:D,$B37)*1/3 -> 0 | M37: =COUNTIF(Fairteilungen!$D:$D,$B37)*3/4 -> 0 | N37: =COUNTIF(Anlieferung!D:D,$B37)*1/2 -> 0 | O37: =COUNTIF(Probeabholungen!B:B,$B37)*1/3 -> 0
A38: Angela Bilger | B38: 224426 | E38: 16 | F38: 6 | G38: =F38-H38 -> 22 | H38: =I38-E38 -> -16 | I38: =SUM(J38:O38) -> 0 | J38: =SUMIF(Oeffentlichkeitsarbeit!$D:$D,$B38,Oeffentlichkeitsarbeit!$F:$F) -> 0 | K38: =COUNTIF(Fairteiler!$D:$D,$B38)*1/2 -> 0 | L38: =COUNTIF('NP-Betrieb'!D:D,$B38)*1/3 -> 0 | M38: =COUNTIF(Fairteilungen!$D:$D,$B38)*3/4 -> 0 | N38: =COUNTIF(Anlieferung!D:D,$B38)*1/2 -> 0 | O38: =COUNTIF(Probeabholungen!B:B,$B38)*1/3 -> 0
A39: Angelique Schubert | B39: 743536 | E39: 1.3333333 | F39: 6 | G39: =F39-H39 -> 7.3333333 | H39: =I39-E39 -> -1.3333333 | I39: =SUM(J39:O39) -> 0 | J39: =SUMIF(Oeffentlichkeitsarbeit!$D:$D,$B39,Oeffentlichkeitsarbeit!$F:$F) -> 0 | K39: =COUNTIF(Fairteiler!$D:$D,$B39)*1/2 -> 0 | L39: =COUNTIF('NP-Betrieb'!D:D,$B39)*1/3 -> 0 | M39: =COUNTIF(Fairteilungen!$D:$D,$B39)*3/4 -> 0 | N39: =COUNTIF(Anlieferung!D:D,$B39)*1/2 -> 0 | O39: =COUNTIF(Probeabholungen!B:B,$B39)*1/3 -> 0
A40: Angelo Fiore | B40: 466403 | E40: 15.67 | F40: 6 | G40: =F40-H40 -> 21.67 | H40: =I40-E40 -> -15.67 | I40: =SUM(J40:O40) -> 0 | J40: =SUMIF(Oeffentlichkeitsarbeit!$D:$D,$B40,Oeffentlichkeitsarbeit!$F:$F) -> 0 | K40: =COUNTIF(Fairteiler!$D:$D,$B40)*1/2 -> 0 | L40: =COUNTIF('NP-Betrieb'!D:D,$B40)*1/3 -> 0 | M40: =COUNTIF(Fairteilungen!$D:$D,$B40)*3/4 -> 0 | N40: =COUNTIF(Anlieferung!D:D,$B40)*1/2 -> 0 | O40: =COUNTIF(Probeabholungen!B:B,$B40)*1/3 -> 0
...

Sheet Oeffentlichkeitsarbeit
A1: Titel json-Dokument | C1: Datum | D1: ID | E1: Name | F1: Exakte Zeit
A2: Öffentlichkeitsarbeit Januar | D2: 729487 | E2: Assia Maaziz-Cinar | F2: 1
A3: Öffentlichkeitsarbeit Januar | D3: 175002 | E3: Detlef Saemann | F3: 4
A4: Öffentlichkeitsarbeit Januar | D4: 646465 | E4: Ellen Reichelt | F4: 3.5
A5: Öffentlichkeitsarbeit Januar | D5: 600132 | E5: Dominik Naschenweng | F5: 4
A6: Öffentlichkeitsarbeit Januar | D6: 239594 | E6: Birgit Lüdecke | F6: 4
A7: Öffentlichkeitsarbeit Januar | D7: 541315 | E7: Juliane Link | F7: 1.5
A8: Öffentlichkeitsarbeit Januar | D8: 621484 | E8: Jonas Maurer | F8: 4
A9: Öffentlichkeitsarbeit Januar | D9: 75350 | E9: Kathrin Mittel | F9: 5
A10: Öffentlichkeitsarbeit Januar | D10: 72661 | E10: Sigrid Endres | F10: 4
A11: Öffentlichkeitsarbeit Januar | D11: 273277 | E11: Johanna Lenzing | F11: 6
A12: Öffentlichkeitsarbeit Januar | D12: 689126 | E12: Steffanie Sennik | F12: 0.5
A13: Öffentlichkeitsarbeit Januar | D13: 682082 | E13: Liliana Alem | F13: 0.5
... A43: Öffentlichkeitsarbeit März | D43: 425464 | E43: Fabiola Mallach | F43: 4
A44: Instagram Februar, März | D44: 588228 | E44: Louisa | F44: =(35+30)/60 -> 1.0833333
A45: Instandhaltung/Aufbau Fairteiler | D45: 413594 | E45: Tomke Aljets | F45: 1.5
A46: Instandhaltung/Aufbau Fairteiler | D46: 557853 | E46: Susanne Boxberg | F46: =1.5+2 -> 3.5
A47: Instandhaltung/Aufbau Fairteiler | D47: 552077 | E47: Felix van Alsberg | F47: =1.5+2 -> 3.5

Sheet Fairteiler
A1: Titel json-Dokument | C1: Datum | D1: ID | E1: Name
A2: 32714_January_2026.json | B2: pickups | C2: 2026-01-02T18:45:00+01:00 | D2: 568663 | E2: Jutta Steinmann
A3: 32714_January_2026.json | B3: pickups | C3: 2026-01-03T17:30:00+01:00 | D3: 830884 | E3: My-Trinh Ngo
A4: 32714_January_2026.json | B4: pickups | C4: 2026-01-05T18:45:00+01:00 | D4: 726889 | E4: Marek Wolczyski
A5: 32714_January_2026.json | B5: pickups | C5: 2026-01-06T18:45:00+01:00 | D5: 830884 | E5: My-Trinh Ngo
A6: 32714_January_2026.json | B6: pickups | C6: 2026-01-07T18:45:00+01:00 | D6: 830884 | E6: My-Trinh Ngo
A7: 32714_January_2026.json | B7: pickups | C7: 2026-01-08T18:45:00+01:00 | D7: 568663 | E7: Jutta Steinmann
A8: 32714_January_2026.json | B8: pickups | C8: 2026-01-09T18:45:00+01:00 | D8: 595661 | E8: Lara Henning
A9: 32714_January_2026.json | B9: pickups | C9: 2026-01-10T17:30:00+01:00 | D9: 636064 | E9: Marie Grell
A10: 32714_January_2026.json | B10: pickups | C10: 2026-01-12T18:45:00+01:00 | D10: 620294 | E10: Magdalena Grieneisen
A11: 32714_January_2026.json | B11: pickups | C11: 2026-01-13T18:45:00+01:00 | D11: 932894 | E11: Jasmin Tsaava
A12: 32714_January_2026.json | B12: pickups | C12: 2026-01-14T18:45:00+01:00 | D12: 830884 | E12: My-Trinh Ngo
A13: 32714_January_2026.json | B13: pickups | C13: 2026-01-15T18:45:00+01:00 | D13: 286123 | E13: Jonas Weber
... A203: 40251_February_2026.json | B203: pickups | C203: 2026-02-27T17:00:00+01:00 | D203: 569123 | E203: Laura Wagner
A204: 52981_February_2026.json | B204: pickups
A205: 53812_February_2026.json | B205: pickups | C205: 2026-02-01T19:00:00+01:00 | D205: 366232 | E205: Christian Kreinert
A206: 53812_February_2026.json | B206: pickups | C206: 2026-02-02T19:00:00+01:00 | D206: 157147 | E206: Lena Elsasser
A207: 53812_February_2026.json | B207: pickups | C207: 2026-02-03T19:00:00+01:00 | D207: 926369 | E207: Farah Mahmoud
A208: 53812_February_2026.json | B208: pickups | C208: 2026-02-04T19:00:00+01:00 | D208: 924566 | E208: Josefin Adams
A209: 53812_February_2026.json | B209: pickups | C209: 2026-02-05T19:00:00+01:00 | D209: 924566 | E209: Josefin Adams
A210: 53812_February_2026.json | B210: pickups | C210: 2026-02-06T19:00:00+01:00 | D210: 821988 | E210: Bernhard Friedrich
A211: 53812_February_2026.json | B211: pickups | C211: 2026-02-07T19:00:00+01:00 | D211: 974730 | E211: Armela Rashidian
A212: 53812_February_2026.json | B212: pickups | C212: 2026-02-08T19:00:00+01:00 | D212: 563635 | E212: Sabrina Sebald
A213: 53812_February_2026.json | B213: pickups | C213: 2026-02-09T19:00:00+01:00 | D213: 761495 | E213: Mikhail Svyatskiy
A214: 53812_February_2026.json | B214: pickups | C214: 2026-02-10T19:00:00+01:00 | D214: 761495 | E214: Mikhail Svyatskiy
A215: 53812_February_2026.json | B215: pickups | C215: 2026-02-11T19:00:00+01:00 | D215: 967920 | E215: Marc Burkhard
A216: 53812_February_2026.json | B216: pickups | C216: 2026-02-12T19:00:00+01:00 | D216: 366232 | E216: Christian Kreinert
... A466: 67344_March_2026.json | B466: pickups | C466: 2026-03-31T19:00:00+02:00 | D466: 717142 | E466: Francis Usinger
A467: 32714_April_2026.json | C467: 2026-04-01T18:45:00+02:00 | D467: 830884 | E467: My-Trinh Ngo
A468: 32714_April_2026.json | C468: 2026-04-02T18:45:00+02:00 | D468: 620294 | E468: Magdalena Grieneisen
A469: 32714_April_2026.json | C469: 2026-04-04T17:30:00+02:00 | D469: 453313 | E469: Anne Altvater
A470: 32714_April_2026.json | C470: 2026-04-07T18:45:00+02:00 | D470: 932894 | E470: Jasmin Tsaava
A471: 32714_April_2026.json | C471: 2026-04-08T18:45:00+02:00 | D471: 932894 | E471: Jasmin Tsaava
A472: 32714_April_2026.json | C472: 2026-04-09T18:45:00+02:00 | D472: 620294 | E472: Magdalena Grieneisen
A473: 32714_April_2026.json | C473: 2026-04-10T18:45:00+02:00 | D473: 665898 | E473: Annika Frohböse
A474: 32714_April_2026.json | C474: 2026-04-11T17:30:00+02:00 | D474: 452434 | E474: Michael Kowol
A475: 32714_April_2026.json | C475: 2026-04-13T18:45:00+02:00 | D475: 95394 | E475: Dana Schneider
A476: 32714_April_2026.json | C476: 2026-04-14T18:45:00+02:00 | D476: 95394 | E476: Dana Schneider
A477: 32714_April_2026.json | C477: 2026-04-15T18:45:00+02:00 | D477: 452434 | E477: Michael Kowol
A478: 32714_April_2026.json | C478: 2026-04-16T18:45:00+02:00 | D478: 568663 | E478: Jutta Steinmann
...

Sheet NP-Betrieb
A1: Titel json-Dokument | B1: Spalte1 | C1: Datum | D1: ID | E1: Name
A2: 1121_January_2026.json | B2: pickups | C2: 2026-01-01T17:00:00+01:00 | D2: 789902 | E2: Maja Krawczyk-Sünder
A3: 1121_January_2026.json | B3: pickups | C3: 2026-01-01T17:00:00+01:00 | D3: 960559 | E3: Katrin Neuser
A4: 1121_January_2026.json | B4: pickups | C4: 2026-01-02T18:00:00+01:00 | D4: 151929 | E4: Cornelia Kisch
A5: 1121_January_2026.json | B5: pickups | C5: 2026-01-02T19:30:00+01:00 | D5: 587311 | E5: Katrin Eckmans
A6: 1121_January_2026.json | B6: pickups | C6: 2026-01-02T19:30:00+01:00 | D6: 748420 | E6: Kübra nur Sencan
A7: 1121_January_2026.json | B7: pickups | C7: 2026-01-02T19:30:00+01:00 | D7: 590029 | E7: Christina Meinert
A8: 1121_January_2026.json | B8: pickups | C8: 2026-01-02T21:00:00+01:00 | D8: 858450 | E8: Tatiana Gheorghita
A9: 1121_January_2026.json | B9: pickups | C9: 2026-01-02T21:00:00+01:00 | D9: 949052 | E9: Mevlüt Yilmaz
A10: 1121_January_2026.json | B10: pickups | C10: 2026-01-03T18:00:00+01:00 | D10: 541315 | E10: Juliane Link
A11: 1121_January_2026.json | B11: pickups | C11: 2026-01-03T20:00:00+01:00 | D11: 964211 | E11: Alexandra Päzolt
A12: 1121_January_2026.json | B12: pickups | C12: 2026-01-03T20:50:00+01:00 | D12: 920008 | E12: Rifat Halili
A13: 1121_January_2026.json | B13: pickups | C13: 2026-01-04T20:00:00+01:00 | D13: 590029 | E13: Christina Meinert
... A27: 1121_January_2026.json | B27: pickups | C27: 2026-01-10T14:15:00+01:00 | D27: 425464 | E27: Fabiola Mallach
A28: 1121_January_2026.json | B28: pickups | C28: 2026-01-10T17:00:00+01:00 | D28: 898806
A29: 1121_January_2026.json | B29: pickups | C29: 2026-01-10T20:30:00+01:00 | D29: 935971 | E29: Ralph Steinborn-Rößler
A30: 1121_January_2026.json | B30: pickups | C30: 2026-01-14T19:00:00+01:00 | D30: 617808 | E30: Amanda Sims
A31: 1121_January_2026.json | B31: pickups | C31: 2026-01-15T19:00:00+01:00 | D31: 340877 | E31: Heidrun Janke
A32: 1121_January_2026.json | B32: pickups | C32: 2026-01-15T20:30:00+01:00 | D32: 162003 | E32: Veronika Hummel
A33: 1121_January_2026.json | B33: pickups | C33: 2026-01-16T17:00:00+01:00 | D33: 959536 | E33: Veronica Wooge
A34: 1121_January_2026.json | B34: pickups | C34: 2026-01-17T10:00:00+01:00 | D34: 378759 | E34: Katharine Cloppenburg
A35: 1121_January_2026.json | B35: pickups | C35: 2026-01-17T19:40:00+01:00 | D35: 628110 | E35: Monja Rößler
A36: 1121_January_2026.json | B36: pickups | C36: 2026-01-17T19:40:00+01:00 | D36: 131287 | E36: Nicole Philipp-Jahnke
A37: 1121_January_2026.json | B37: pickups | C37: 2026-01-17T19:45:00+01:00 | D37: 828268 | E37: Aline Eckert
A38: 1121_January_2026.json | B38: pickups | C38: 2026-01-17T19:45:00+01:00 | D38: 920008 | E38: Rifat Halili
A39: 1121_January_2026.json | B39: pickups | C39: 2026-01-17T20:50:00+01:00 | D39: 689981 | E39: Roswitha Bevilacqua
A40: 1121_January_2026.json | B40: pickups | C40: 2026-01-19T19:30:00+01:00 | D40: 875441 | E40: Christoph Lokotsch-Schmidt
... A1535: 63665_February_2026.json | B1535: pickups | C1535: 2026-02-27T18:00:00+01:00 | D1535: 967569 | E1535: Oksana Braun
A1536: 64191_February_2026.json | B1536: pickups
A1537: 64491_February_2026.json | B1537: pickups | C1537: 2026-02-02T07:00:00+01:00 | D1537: 571329 | E1537: Iryna Korolyova
A1538: 64491_February_2026.json | B1538: pickups | C1538: 2026-02-03T07:00:00+01:00 | D1538: 872540 | E1538: Stefan Becker
A1539: 64491_February_2026.json | B1539: pickups | C1539: 2026-02-04T07:00:00+01:00 | D1539: 618122 | E1539: Torsten Sillke
A1540: 64491_February_2026.json | B1540: pickups | C1540: 2026-02-05T07:00:00+01:00 | D1540: 974730 | E1540: Armela Rashidian
A1541: 64491_February_2026.json | B1541: pickups | C1541: 2026-02-06T15:30:00+01:00 | D1541: 618122 | E1541: Torsten Sillke
A1542: 64491_February_2026.json | B1542: pickups | C1542: 2026-02-09T07:00:00+01:00 | D1542: 910059 | E1542: Leona Rath
A1543: 64491_February_2026.json | B1543: pickups | C1543: 2026-02-10T07:00:00+01:00 | D1543: 618122 | E1543: Torsten Sillke
A1544: 64491_February_2026.json | B1544: pickups | C1544: 2026-02-11T07:00:00+01:00 | D1544: 872540 | E1544: Stefan Becker
A1545: 64491_February_2026.json | B1545: pickups | C1545: 2026-02-12T07:00:00+01:00 | D1545: 872540 | E1545: Stefan Becker
A1546: 64491_February_2026.json | B1546: pickups | C1546: 2026-02-13T15:30:00+01:00 | D1546: 618122 | E1546: Torsten Sillke
A1547: 64491_February_2026.json | B1547: pickups | C1547: 2026-02-16T07:00:00+01:00 | D1547: 618122 | E1547: Torsten Sillke
...

Sheet Fairteilungen
A1: Titel json-Dokument | C1: Datum | D1: ID | E1: Name

Sheet Anlieferung
A1: Titel json-Dokument | C1: Datum | D1: ID | E1: Name
A2: 59966_January_2026.json | B2: pickups | C2: 2026-01-06T20:00:00+01:00 | D2: 597434 | E2: Anita Lemaile
A3: 59966_January_2026.json | B3: pickups | C3: 2026-01-06T20:00:00+01:00 | D3: 829843 | E3: Ute van Beuningen
A4: 59966_January_2026.json | B4: pickups | C4: 2026-01-06T20:00:00+01:00 | D4: 302414 | E4: Monika Hutwelker
A5: 59966_January_2026.json | B5: pickups | C5: 2026-01-13T20:00:00+01:00 | D5: 302414 | E5: Monika Hutwelker
A6: 59966_January_2026.json | B6: pickups | C6: 2026-01-13T20:00:00+01:00 | D6: 597434 | E6: Anita Lemaile
A7: 59966_January_2026.json | B7: pickups | C7: 2026-01-13T20:00:00+01:00 | D7: 829843 | E7: Ute van Beuningen
A8: 59966_January_2026.json | B8: pickups | C8: 2026-01-20T20:00:00+01:00 | D8: 597434 | E8: Anita Lemaile
A9: 59966_January_2026.json | B9: pickups | C9: 2026-01-20T20:00:00+01:00 | D9: 500961 | E9: Mojda Helmand
A10: 59966_January_2026.json | B10: pickups | C10: 2026-01-27T20:00:00+01:00 | D10: 597434 | E10: Anita Lemaile
A11: 59966_January_2026.json | B11: pickups | C11: 2026-01-27T20:00:00+01:00 | D11: 914365 | E11: Maria Mokhova
A12: 59966_March_2026.json | B12: pickups | C12: 2026-03-03T20:00:00+01:00 | D12: 597434 | E12: Anita Lemaile
A13: 59966_March_2026.json | B13: pickups | C13: 2026-03-03T20:00:00+01:00 | D13: 302414 | E13: Monika Hutwelker
... A56: 67643_April_2026.json | B56: .json | C56: 2026-04-23T22:00:00+02:00 | D56: 905187 | E56: Tatjana Abich
A57: 68127_April_2026.json | B57: .json

Sheet Probeabholungen
A1: Monat | B1: ID | C1: Name
A2: Januar | B2: 479121 | C2: Andrea Heymann
A3: Januar | B3: 831512 | C3: Annette Prohl
A4: Januar | B4: 635374 | C4: Lisa Gonzalez
A5: Januar | B5: 636064 | C5: Marie Grell
A6: Januar | B6: 162003 | C6: Veronika Hummel
A7: Januar | B7: 629424 | C7: Anja Lobbenmeier
A8: Januar | B8: 267168 | C8: Doris Peck
A9: Januar | B9: 132132 | C9: Lisa Weipert
A10: Januar | B10: 903811 | C10: Isabel Händler
A11: Januar | B11: 496044 | C11: Katja Hofmaier
A12: Januar | B12: 803535 | C12: Sonja Stamm
A13: Januar | B13: 248981 | C13: Alicia Koch
... A104: März | B104: 803535 | C104: Sonja Stamm

Sheet Betriebe
A1: Name Betrieb | B1: URL | C1: Kategorie | D1: ID | E1: Januar | F1: Februar | G1: März | H1: April | I1: Mai | J1: Juni | K1: Juli | L1: August | M1: September | N1: Oktober | O1: November | P1: Dezember
A2: Noteinsatz | C2: NP-Betrieb | D2: 1121 | E2: json | F2: json | G2: json | H2: json
A3: Café Tradita | B3: https://foodsharing.de/store/3738 | C3: NP-Betrieb | D3: 3738 | E3: json | F3: json | G3: json | H3: json
A4: Bäckerei Rausch Bornheim | B4: https://foodsharing.de/store/4061 | C4: NP-Betrieb | D4: 4061 | E4: json | F4: json | G4: json | H4: json
A5: Krabbelstube Kullerwiese | B5: https://foodsharing.de/store/4995 | C5: NP-Betrieb | D5: 4995 | E5: json | F5: json | G5: json | H5: json
A6: MokkaTeeria | B6: https://foodsharing.de/store/12483 | C6: NP-Betrieb | D6: 12483 | E6: json | F6: json | G6: json | H6: json
A7: Dein Backhaus (ehem. Billback) | B7: https://foodsharing.de/store/12530 | C7: NP-Betrieb | D7: 12530 | E7: json | F7: json | G7: json | H7: json
A8: Wochenmarkt Bornheim | B8: https://foodsharing.de/store/12984 | C8: NP-Betrieb | D8: 12984 | E8: json | F8: json | G8: json | H8: json
A9: Wochenmarkt Südbahnhof | B9: https://foodsharing.de/store/15150 | C9: NP-Betrieb | D9: 15150 | E9: json | F9: json | G9: json | H9: json
A10: Intermarkt | B10: https://foodsharing.de/store/18561 | C10: NP-Betrieb | D10: 18561 | E10: json | F10: json | G10: json | H10: json
A11: Kaisermarkt Frankfurt (da Bäcker Stand) | B11: https://foodsharing.de/store/18862 | C11: NP-Betrieb | D11: 18862 | E11: json | F11: json | G11: json | H11: json
A12: Wochenmarkt Schillermarkt | B12: https://foodsharing.de/store/21728 | C12: NP-Betrieb | D12: 21728 | E12: json | F12: json | G12: json | H12: json
A13: Vogelsbergbäcker | B13: https://foodsharing.de/store/24590 | C13: NP-Betrieb | D13: 24590 | E13: json | F13: json | G13: json | H13: json
A14: Wochenmarkt Konstablerwache | B14: https://foodsharing.de/store/25330 | C14: NP-Betrieb | D14: 25330 | E14: json | F14: json | G14: json | H14: json
... A22: Fairteiler Bornheim | B22: https://foodsharing.de/store/32714 | C22: Fairteiler | D22: 32714 | E22: json | F22: json | G22: json | H22: json
A23: Zweigstelle Reformhaus Andersch | C23: NP-Betrieb | D23: 32347 | E23: ab Februar 2026 | F23: json | G23: json | H23: json
A24: K&B Bäckerei Schloßstraße | B24: https://foodsharing.de/store/33087 | C24: NP-Betrieb | D24: 33087 | E24: json | F24: json | G24: json | H24: json
A25: Café Frankfurt (Gutleut) | B25: https://foodsharing.de/store/39396 | C25: geschlossen | D25: 39396 | E25: leer | F25: leer | G25: leer | H25: leer
A26: Fairteiler Ada-Kantine | B26: https://foodsharing.de/store/40251 | C26: Fairteiler | D26: 40251 | E26: json | F26: json | G26: json | H26: json
A27: K&B Bäckerei Oeder Weg | B27: https://foodsharing.de/store/34060 | C27: NP-Betrieb | D27: 34060 | E27: json | F27: json | G27: json | H27: json
A28: Quicker ́s Flughafen, Terminal 1 Ankunft A | B28: https://foodsharing.de/store/42641 | C28: geschlossen | D28: 42641 | E28: leer | F28: leer | G28: leer | H28: leer
A29: Quicker ́s Hauptbahnhof | B29: https://foodsharing.de/store/42648 | C29: geschlossen | D29: 42648 | E29: leer | F29: leer | G29: leer | H29: leer
A30: Bäckerei im Scheck in Center Sachsenhausen | B30: https://foodsharing.de/store/41891 | C30: NP-Betrieb | D30: 41891 | E30: json | F30: json | G30: json | H30: json
A31: Bäckerei Cafe BIBI | B31: https://foodsharing.de/store/45407 | C31: NP-Betrieb | D31: 45407 | E31: json | F31: json | G31: json | H31: json
A32: Dünsberg Bäcker auf dem Wochenmarkt in Heddernheim | B32: https://foodsharing.de/store/45984 | C32: NP-Betrieb | D32: 45984 | E32: json | F32: json | G32: json | H32: json
A33: Foodji | C33: NP-Betrieb | D33: 46028 | E33: json | F33: json | G33: json | H33: json
A34: Tegut Kaiserstraße | B34: https://foodsharing.de/store/47643 | C34: NP-Betrieb | D34: 47643 | E34: json | F34: json | G34: json | H34: json
A35: Bäckerei Antika | B35: https://foodsharing.de/store/49255 | C35: NP-Betrieb | D35: 49255 | E35: json | F35: json | G35: json | H35: json
A36: Öffentlichskeitarbeit | B36: https://foodsharing.de/store/52831 | C36: Ö-Arbeit | D36: 52831 | E36: *json | F36: *json | G36: *json
A37: Fairteiler Höchst | B37: https://foodsharing.de/store/53812 | C37: Fairteiler | D37: 53812 | E37: json | F37: json | G37: json | H37: json
A38: Kita Brandhöfchen | B38: https://foodsharing.de/store/50404 | C38: NP-Betrieb | D38: 50404 | E38: json | F38: json | G38: json | H38: json
A39: Fairteiler Schwanheim | B39: https://foodsharing.de/store/57579 | C39: Fairteiler | D39: 57579 | E39: json | F39: json | G39: json | H39: json
A40: Penny Leipziger Straße | B40: https://foodsharing.de/store/50487 | C40: NP-Betrieb | D40: 50487 | E40: json | F40: json | G40: json | H40: json
A41: Penny Bonames | C41: NP-Betrieb | D41: 50480 | I41: NP ab 01.06.2026
A42: Rewe Junker Frankenallee (Gallus) | C42: NP-Betrieb | D42: 51699 | E42: ab Februar 2026 | F42: json | G42: json | H42: json
A43: Rewe Sachsenhausen | B43: https://foodsharing.de/store/57036 | C43: NP-Betrieb | D43: 57036 | E43: json | F43: json | G43: json | H43: json
A44: Steigenberger Airport Hotel - Frankfurt | B44: https://foodsharing.de/store/57673 | C44: NP-Betrieb | D44: 57673 | E44: json | F44: json | G44: json | H44: json
A45: Schul-Catering Konradhof: Carl-von-Weinberg-Schule Goldstein | B45: https://foodsharing.de/store/57964 | C45: NP-Betrieb | D45: 57964 | E45: json | F45: json | G45: json | H45: json
A46: LM-Anlieferung Nachbarschaftstreff „Nebenan“ | B46: https://foodsharing.de/store/59966 | C46: Anlieferung | D46: 59966 | E46: json | F46: json | G46: json | H46: json
A47: Waldstation Supreme Sports Hospitality | B47: https://foodsharing.de/store/58223 | C47: NP-Betrieb | D47: 58223 | E47: json | F47: json | G47: json | H47: json
...

Sheet Farbcodes
A1: Persönliche Gründe
A2: Alter
A3: Erreicht
A4: Posten
A6: Zweitmitglied (nur relevant für 23)
